Workbook

Sheet Unjuk Kerja
A1: Unjuk Kerja Unit Proses dan Unit Operasi
A2: No | B2: Unit Proses / Unit Operasi | C2: Parameter Unjuk Kerja | D2: Nilai | E2: Keterangan | F2: Referensi
A3: 1 | B3: Reaktor Klorinasi Langsung (R-01) | C3: Rasio mol umpan C₂H₄/Cl₂ | D3: 1.004 | E3: Jumlah etilena zona 1 (99.5 %-mol) dan zona 2 (0.9 %-mol) terhadap Cl₂ murni | F3: U.S. Patent No. 4,072,728 (1978), Contoh 1
A4: 2 | B4: Reaktor Klorinasi Langsung (R-01) | C4: Kehilangan Cl₂ | D4: < 0.01 % | E4: Fraksi Cl₂ umpan yang tidak bereaksi, dipakai 0.01 % (batas atas) | F4: U.S. Patent No. 4,072,728 (1978), Contoh 1
A5: 3 | B5: Reaktor Klorinasi Langsung (R-01) | C5: Kadar 1,1,2-trikloroetana dalam EDC | D5: 300 ppm | E5: Basis berat, menentukan laju reaksi pembentukan TCE | F5: U.S. Patent No. 4,072,728 (1978), Contoh 1
A6: 4 | B6: Reaktor Klorinasi Langsung (R-01) | C6: Kadar FeCl₃ terlarut dalam EDC | D6: 200 ppm | E6: Paten tidak menyebut basisnya, dihitung sebagai fraksi berat untuk make-up FeCl₃ | F6: U.S. Patent No. 4,072,728 (1978), Contoh 1
A7: 5 | B7: Kondensor Vent R-01 | C7: EDC terbawa gas vent | D7: 1.08 kg/t EDC | E7: Per ton EDC yang dihasilkan proses seimbang (R-01 + R-02), sebelum alat pengendali emisi. Gas inert, etilena sisa, Cl₂ sisa, dan HCl keluar sebagai vent | F7: U.S. EPA (1984) EPA-450/4-84-007d, Tabel 2 (Vent B)
A8: 6 | B8: Reaktor Oksiklorinasi (R-02) | C8: Rasio mol umpan C₂H₄ : O₂ : HCl | D8: 1.0 : 0.8 : 2.0 | E8: Oksigen dipasok sebagai udara | F8: U.S. Patent No. 4,740,642 (1988)
A9: 7 | B9: Reaktor Oksiklorinasi (R-02) | C9: Konversi C₂H₄ | D9: 99.5 % | E9: Fraksi etilena umpan yang bereaksi | F9: U.S. Patent No. 4,740,642 (1988), Contoh I no. 6
A10: 8 | B10: Reaktor Oksiklorinasi (R-02) | C10: Efisiensi C₂H₄ menjadi EDC | D10: 98.2 % | E10: Mol EDC terbentuk per mol etilena umpan | F10: U.S. Patent No. 4,740,642 (1988), Contoh I no. 6
A11: 9 | B11: Reaktor Oksiklorinasi (R-02) | C11: Konversi HCl | D11: 98.6 % | E11: Nilai terkoreksi | F11: U.S. Patent No. 4,740,642 (1988), Contoh I no. 6
A12: 10 | B12: Reaktor Oksiklorinasi (R-02) | C12: Produk samping | D12: C₂H₅Cl dan CO₂ | E12: Etil klorida termasuk produk samping paling banyak dan etilena juga teroksidasi menjadi COₓ. Jumlahnya dihitung dari selisih konversi, efisiensi, dan konversi HCl paten | F12: Montebelli dkk. (2015); BREF LVOC (2017) Bab 11
A13: 11 | B13: Udara Umpan R-02 | C13: Fraksi mol O₂ dalam udara | D13: 0.21 | E13: Fraksi mol N₂ 0.79 | F13: Smith dkk. (2018) Tabel B.1
A14: 12 | B14: Kondensor dan Dekanter | C14: EDC terbawa gas vent | D14: 2.40 kg/t EDC | E14: Proses udara dengan kondensor berpendingin, per ton EDC yang dihasilkan R-01 + R-02. O₂, N₂, CO₂, etilena, dan etana keluar sebagai vent | F14: U.S. EPA (1984) EPA-450/4-84-007d, Tabel 2 (Vent A)
... A37: 35 | B37: Kolom VCM (KD-104) | C37: Beban kondensor | D37: 2.98 MW | E37: Dipakai untuk menurunkan rasio refluks | F37: Dimian & Bildea (2008) Tabel 7.8

Sheet MASTER
A3: Neraca Massa
A4: NM Unit xx (xx)
A5: Tujuan:
A6: Unjuk Kerja
A9: Basis Perhitungan
A10: Substance | B10: Inlet | J10: Outlet
B11: Aliran 1 | F11: Aliran 2 | J11: Aliran 3 | N11: Aliran 4
B12: ẋᵢ | C12: ṁᵢ (kg/h) | D12: ẏᵢ | E12: ṅᵢ (kmol/h) | F12: ẋᵢ | G12: ṁᵢ (kg/h) | H12: ẏᵢ | I12: ṅᵢ (kmol/h) | J12: ẋᵢ | K12: ṁᵢ (kg/h) | L12: ẏᵢ | M12: ṅᵢ (kmol/h) | N12: ẋᵢ | O12: ṁᵢ (kg/h) | P12: ẏᵢ | Q12: ṅᵢ (kmol/h)
A13: A (x)
A14: B (x)
A15: C (x)
A16: Sub Total | B16: =SUM(B13:B15) -> 0 | C16: =SUM(C13:C15) -> 0 | D16: =SUM(D13:D15) -> 0 | E16: =SUM(E13:E15) -> 0 | F16: =SUM(F13:F15) -> 0 | G16: =SUM(G13:G15) -> 0 | H16: =SUM(H13:H15) -> 0 | I16: =SUM(I13:I15) -> 0 | ... Q16: =SUM(Q13:Q15) -> 0
A17: TOTAL MASSA | B17: =SUMPRODUCT(B13:B15,C13:C15) + SUMPRODUCT(F13:F15,G13:G15) -> 0 | J17: =SUMPRODUCT(J13:J15,K13:K15) + SUMPRODUCT(N13:N15,O13:O15) -> 0
A19: Neraca Energi
A20: Reference State:
A21: Substance | B21: Inlet | F21: Outlet
B22: Aliran 1 | D22: Aliran 2 | F22: Aliran 3 | H22: Aliran 4
B23: ṅᵢ (kmol/h) | C23: Ḣᵢ,ᵢₙ (kJ/kmol) | D23: ṅᵢ (kmol/h) | E23: Ḣᵢ,ᵢₙ (kJ/kmol) | F23: ṅᵢ (kmol/h) | G23: Ḣᵢ,ₒᵤₜ (kJ/kmol) | H23: ṅᵢ (kmol/h) | I23: Ḣᵢ,ₒᵤₜ (kJ/kmol)
A24: A (x)
A25: B (x)
A26: C (x)
A27: Sub Total | B27: =SUMPRODUCT(B24:B26,C24:C26) -> 0 | D27: =SUMPRODUCT(D24:D26,E24:E26) -> 0 | F27: =SUMPRODUCT(F24:F26,G24:G26) -> 0 | H27: =SUMPRODUCT(H24:H26,I24:I26) -> 0
A28: Heat of mixing/heat of reaction
A29: Q or W
A30: TOTAL

Sheet T-101
A1: Spesifikasi klorin umpan wt%
A2: CₙHₘ | B2: =4/1000000 -> 4e-06
A3: Water | B3: =12/1000000 -> 1.2e-05
A4: CₓHᵧCl | B4: =8/1000000 -> 8e-06
A5: Bromine | B5: =90/1000000 -> 9e-05
A6: Nitrogen trichloride | B6: =5/1000000 -> 5e-06
A7: Hydrogen | B7: =30/1000000 -> 3e-05
A8: Oxygen | B8: =180/1000000 -> 0.00018
A9: Nitrogen | B9: =600/1000000 -> 0.0006
A10: Carbon dioxide | B10: =600/1000000 -> 0.0006
A11: Fraksi berat Cl₂ = 1 − Σ pengotor | B11: =1-SUM(B2:B10) -> 0.998471

Sheet T-102
A1: Basis | B1: 1 | C1: m^3
A2: Component | B2: Unit | C2: Value (m^3) | D2: T | E2: P | F2: Mw | G2: ω | H2: Tc (K) | I2: Pc (bar) | J2: Tr | K2: Pr | L2: σ | M2: ε | N2: Ω | O2: Ψ | P2: Zc | Q2: αPR(Tr; ω)* | R2: β | S2: q​ | T2: Z | U2: Zres | V2: ρ | W2: mass (kg) | X2: %wt
A3: Ethylene Purity | B3: Volume% | C3: =1-SUM(C4:C6) -> 0.999485 | D3: 303.15 | E3: 36.3 | F3: 28.054 | G3: 0.087 | H3: 282.3 | I3: 50.4 | J3: =D3/H3 -> 1.0738576 | K3: =E3/I3 -> 0.7202381 | L3: =1+SQRT(2) -> 2.4142136 | M3: =1-SQRT(2) -> -0.41421356 | N3: 0.0778 | O3: 0.45724 | P3: 0.3074 | Q3: =(1+(0.37464+1.54226*G3-0.26992*G3^2)*(1-SQRT(J3)))^2 -> 0.96357549 | R3: =N3*K3/J3 -> 0.052180591 | S3: =O3*Q3/(N3*J3) -> 5.2735573 | T3: 0.75191292 | U3: =T3-(R3+(T3+M3*R3)*(T3+L3*R3)*((1+R3-T3)/(S3*R3))) -> 0.00015497478 | V3: =E3*100*F3/(T3*8.314*D3) -> 53.736116 | W3: =V3*C3 -> 53.708442 | X3: =W3/$W$7 -> 0.99975105
A4: Methane | B4: Volume% | C4: =500/1000000*1 -> 0.0005 | D4: 303.15 | E4: 36.3 | F4: 16.043 | G4: 0.012 | H4: 190.6 | I4: 45.99 | J4: =D4/H4 -> 1.5905037 | K4: =E4/I4 -> 0.78930202 | L4: =1+SQRT(2) -> 2.4142136 | M4: =1-SQRT(2) -> -0.41421356 | N4: 0.0778 | O4: 0.45724 | P4: 0.3074 | Q4: =(1+(0.37464+1.54226*G4-0.26992*G4^2)*(1-SQRT(J4)))^2 -> 0.80521746 | R4: =N4*K4/J4 -> 0.038608963 | S4: =O4*Q4/(N4*J4) -> 2.9753847 | T4: 0.92902928 | U4: =T4-(R4+(T4+M4*R4)*(T4+L4*R4)*((1+R4-T4)/(S4*R4))) -> 0.00011328207 | V4: =E4*100*F4/(T4*8.314*D4) -> 24.871113 | W4: =V4*C4 -> 0.012435556 | X4: =W4/$W$7 -> 0.00023148056
A5: Ethane | B5: Volume% | C5: =10/1000000 -> 1e-05 | D5: 303.15 | E5: 36.3 | F5: 30.07 | G5: 0.1 | H5: 305.3 | I5: 48.72 | J5: =D5/H5 -> 0.99295775 | K5: =E5/I5 -> 0.74507389 | L5: =1+SQRT(2) -> 2.4142136 | M5: =1-SQRT(2) -> -0.41421356 | N5: 0.0778 | O5: 0.45724 | P5: 0.3074 | Q5: =(1+(0.37464+1.54226*G5-0.26992*G5^2)*(1-SQRT(J5)))^2 -> 1.0037154 | R5: =N5*K5/J5 -> 0.05837786 | S5: =O5*Q5/(N5*J5) -> 5.9407932 | T5: 0.63818214 | U5: =T5-(R5+(T5+M5*R5)*(T5+L5*R5)*((1+R5-T5)/(S5*R5))) -> 0.00019954088 | V5: =E5*100*F5/(T5*8.314*D5) -> 67.862181 | W5: =V5*C5 -> 0.00067862181 | X5: =W5/$W$7 -> 1.2632146e-05
A6: Acetylene | B6: Volume% | C6: =5/1000000 -> 5e-06 | D6: 303.15 | E6: 36.3 | F6: 26.038 | G6: 0.187 | H6: 308.3 | I6: 61.39 | J6: =D6/H6 -> 0.98329549 | K6: =E6/I6 -> 0.59130151 | L6: =1+SQRT(2) -> 2.4142136 | M6: =1-SQRT(2) -> -0.41421356 | N6: 0.0778 | O6: 0.45724 | P6: 0.3074 | Q6: =(1+(0.37464+1.54226*G6-0.26992*G6^2)*(1-SQRT(J6)))^2 -> 1.0109942 | R6: =N6*K6/J6 -> 0.046784775 | S6: =O6*Q6/(N6*J6) -> 6.0426748 | T6: 0.72141147 | U6: =T6-(R6+(T6+M6*R6)*(T6+L6*R6)*((1+R6-T6)/(S6*R6))) -> 0.00047310194 | V6: =E6*100*F6/(T6*8.314*D6) -> 51.983272 | W6: =V6*C6 -> 0.00025991636 | X6: =W6/$W$7 -> 4.8381901e-06
A7: Total Mass | W7: =SUM(W3:W6) -> 53.721816 | X7: =SUM(X3:X6) -> 1

Sheet Data Komponen
A1: Data Berat Molekul Komponen
A2: No | B2: Komponen | C2: Kode | D2: BM (kg/kmol)
A3: 1 | B3: Ethylene Purity | C3: C2H4 | D3: 28.054
A4: 2 | B4: Methane | C4: CH4 | D4: 16.043
A5: 3 | B5: Ethane | C5: C2H6 | D5: 30.07
A6: 4 | B6: Acetylene | C6: C2H2 | D6: 26.038
A7: 5 | B7: Chlorine | C7: Cl2 | D7: 70.905
A8: 6 | B8: CₙHₘ | C8: CnHm | D8: 16.043
A9: 7 | B9: Water | C9: H2O | D9: 18.015
A10: 8 | B10: CₓHᵧCl | C10: CxHyCl | D10: 50.488
A11: 9 | B11: Bromine | C11: Br2 | D11: 159.808
A12: 10 | B12: Nitrogen trichloride | C12: NCl3 | D12: 120.365
A13: 11 | B13: Hydrogen | C13: H2 | D13: 2.016
A14: 12 | B14: Oxygen | C14: O2 | D14: 31.999
... A23: 21 | B23: Fraksi berat (C₄H₈Cl₂) | C23: HVY | D23: 127.013

Sheet Data Termo
A1: Data Termodinamika Komponen (metode panas pembentukan, reference state: unsur pada 25 °C, 1 atm)
A2: Cp gas = A + BT + CT² + DT³ + ET⁴; Cp cair = A + BT + CT² + DT³; Cp padat = A + BT + CT² (J/(mol·K) = kJ/(kmol·K), T dalam K). ΔHvap = A(1 − T/Tc)ⁿ (kJ/mol). Sumber: Yaws, C.L. (1999) Chemical Properties Handbook, McGraw-Hill.
E4: Cp gas ideal (Tabel 2-1 / 2-2) | J4: Cp cair (Tabel 3-1 / 3-2) | N4: Cp padat (Tabel 4-2) | Q4: ΔHvap (Tabel 5-1 / 5-2) | T4: Pembentukan (Tabel 12-1 / 12-2) | V4: Entalpi
A5: No | B5: Kode | C5: Komponen | D5: BM | E5: A | F5: B | G5: C | H5: D | I5: E | J5: A | K5: B | L5: C | M5: D | N5: A | O5: B | P5: C | Q5: A (kJ/mol) | R5: Tc (K) | S5: n | T5: ΔHf° 298 (kJ/mol) | U5: Fase ΔHf° | V5: ΔHvap 298 K (kJ/kmol) | W5: Ĥ° gas 298 K (kJ/kmol) | X5: Ĥ° cair 298 K (kJ/kmol)
A6: 1 | B6: C2H4 | C6: C₂H₄ | D6: ='Data Komponen'!$D$3 -> 28.054 | E6: 32.083 | F6: -0.014831 | G6: 0.00024774 | H6: -2.3766e-07 | I6: 6.8274e-11 | J6: - | K6: - | L6: - | M6: - | N6: - | O6: - | P6: - | Q6: 19.986 | R6: 282.36 | S6: 0.431 | T6: 52.3 | U6: gas | V6: =Q6*1000*MAX(0,1-298.15/R6)^S6 -> 0 | W6: =T6*1000 -> 52300 | X6: -
A7: 2 | B7: CH4 | C7: CH₄ | D7: ='Data Komponen'!$D$4 -> 16.043 | E7: 34.942 | F7: -0.039957 | G7: 0.00019184 | H7: -1.5303e-07 | I7: 3.9321e-11 | J7: - | K7: - | L7: - | M7: - | N7: - | O7: - | P7: - | Q7: 10.312 | R7: 190.58 | S7: 0.265 | T7: -74.85 | U7: gas | V7: =Q7*1000*MAX(0,1-298.15/R7)^S7 -> 0 | W7: =T7*1000 -> -74850 | X7: -
A8: 3 | B8: C2H6 | C8: C₂H₆ | D8: ='Data Komponen'!$D$5 -> 30.07 | E8: 28.146 | F8: 0.043447 | G8: 0.00018946 | H8: -1.9082e-07 | I8: 5.3349e-11 | J8: - | K8: - | L8: - | M8: - | N8: - | O8: - | P8: - | Q8: - | R8: - | S8: - | T8: -84.68 | U8: gas | V8: - | W8: =T8*1000 -> -84680 | X8: -
A9: 4 | B9: C2H2 | C9: C₂H₂ | D9: ='Data Komponen'!$D$6 -> 26.038 | E9: 19.36 | F9: 0.11519 | G9: -0.00012374 | H9: 7.237e-08 | I9: -1.659e-11 | J9: - | K9: - | L9: - | M9: - | N9: - | O9: - | P9: - | Q9: - | R9: - | S9: - | T9: 226.73 | U9: gas | V9: - | W9: =T9*1000 -> 226730 | X9: -
A10: 5 | B10: Cl2 | C10: Cl₂ | D10: ='Data Komponen'!$D$7 -> 70.905 | E10: 27.213 | F10: 0.030426 | G10: -3.3353e-05 | H10: 1.5961e-08 | I10: -2.7021e-12 | J10: 127.601 | K10: -0.60215 | L10: 0.0015776 | M10: -5.3099e-07 | N10: - | O10: - | P10: - | Q10: 28.56 | R10: 417.15 | S10: 0.401 | T10: 0 | U10: gas | V10: =Q10*1000*MAX(0,1-298.15/R10)^S10 -> 17270.915 | W10: =T10*1000 -> 0 | X10: =T10*1000-V10 -> -17270.915
A11: 6 | B11: CnHm | C11: CₙHₘ | D11: ='Data Komponen'!$D$8 -> 16.043 | E11: 34.942 | F11: -0.039957 | G11: 0.00019184 | H11: -1.5303e-07 | I11: 3.9321e-11 | J11: - | K11: - | L11: - | M11: - | N11: - | O11: - | P11: - | Q11: 10.312 | R11: 190.58 | S11: 0.265 | T11: -74.85 | U11: gas | V11: =Q11*1000*MAX(0,1-298.15/R11)^S11 -> 0 | W11: =T11*1000 -> -74850 | X11: -
A12: 7 | B12: H2O | C12: H₂O | D12: ='Data Komponen'!$D$9 -> 18.015 | E12: 33.933 | F12: -0.0084186 | G12: 2.9906e-05 | H12: -1.7825e-08 | I12: 3.6934e-12 | J12: 92.053 | K12: -0.039953 | L12: -0.00021103 | M12: 5.3469e-07 | N12: - | O12: - | P12: - | Q12: 52.053 | R12: 647.13 | S12: 0.321 | T12: -241.8 | U12: gas | V12: =Q12*1000*MAX(0,1-298.15/R12)^S12 -> 42692.979 | W12: =T12*1000 -> -241800 | X12: =T12*1000-V12 -> -284492.98
A13: 8 | B13: CxHyCl | C13: CₓHᵧCl | D13: ='Data Komponen'!$D$10 -> 50.488 | E13: 27.385 | F13: 0.026036 | G13: 0.0001032 | H13: -1.0887e-07 | I13: 3.1642e-11 | J13: - | K13: - | L13: - | M13: - | N13: - | O13: - | P13: - | Q13: 32.534 | R13: 416.25 | S13: 0.452 | T13: -86.32 | U13: gas | V13: =Q13*1000*MAX(0,1-298.15/R13)^S13 -> 18409.682 | W13: =T13*1000 -> -86320 | X13: -
A14: 9 | B14: Br2 | C14: Br₂ | D14: ='Data Komponen'!$D$11 -> 159.808 | E14: 27.169 | F14: 0.049172 | G14: -8.5027e-05 | H14: 6.2796e-08 | I14: -1.6556e-11 | J14: 165.688 | K14: -0.65579 | L14: 0.0013794 | M14: -6.0832e-07 | N14: - | O14: - | P14: - | Q14: 41.279 | R14: 584.15 | S14: 0.38 | T14: 30.9 | U14: gas | V14: =Q14*1000*MAX(0,1-298.15/R14)^S14 -> 31467.989 | W14: =T14*1000 -> 30900 | X14: =T14*1000-V14 -> -567.98943
A15: 10 | B15: NCl3 | C15: NCl₃ | D15: ='Data Komponen'!$D$12 -> 120.365 | E15: - | F15: - | G15: - | H15: - | I15: - | J15: 192.643 | K15: -0.61039 | L15: 0.0010601 | M15: -6.3674e-08 | N15: - | O15: - | P15: - | Q15: 43.544 | R15: 564 | S15: 0.38 | T15: 230 | U15: cair | V15: =Q15*1000*MAX(0,1-298.15/R15)^S15 -> 32719.314 | W15: =T15*1000+V15 -> 262719.31 | X15: =T15*1000 -> 230000
A16: 11 | B16: H2 | C16: H₂ | D16: ='Data Komponen'!$D$13 -> 2.016 | E16: 25.399 | F16: 0.020178 | G16: -3.8549e-05 | H16: 3.188e-08 | I16: -8.7585e-12 | J16: - | K16: - | L16: - | M16: - | N16: - | O16: - | P16: - | Q16: - | R16: - | S16: - | T16: 0 | U16: gas | V16: - | W16: =T16*1000 -> 0 | X16: -
A17: 12 | B17: O2 | C17: O₂ | D17: ='Data Komponen'!$D$14 -> 31.999 | E17: 29.526 | F17: -0.0088999 | G17: 3.8083e-05 | H17: -3.2629e-08 | I17: 8.8607e-12 | J17: - | K17: - | L17: - | M17: - | N17: - | O17: - | P17: - | Q17: - | R17: - | S17: - | T17: 0 | U17: gas | V17: - | W17: =T17*1000 -> 0 | X17: -
A18: 13 | B18: N2 | C18: N₂ | D18: ='Data Komponen'!$D$15 -> 28.014 | E18: 29.342 | F18: -0.0035395 | G18: 1.0076e-05 | H18: -4.3116e-09 | I18: 2.5935e-13 | J18: - | K18: - | L18: - | M18: - | N18: - | O18: - | P18: - | Q18: - | R18: - | S18: - | T18: 0 | U18: gas | V18: - | W18: =T18*1000 -> 0 | X18: -
A19: 14 | B19: CO2 | C19: CO₂ | D19: ='Data Komponen'!$D$16 -> 44.01 | E19: 27.437 | F19: 0.042315 | G19: -1.9555e-05 | H19: 3.9968e-09 | I19: -2.9872e-13 | J19: - | K19: - | L19: - | M19: - | N19: - | O19: - | P19: - | Q19: - | R19: - | S19: - | T19: -393.5 | U19: gas | V19: - | W19: =T19*1000 -> -393500 | X19: -
A20: 15 | B20: EDC | C20: EDC | D20: ='Data Komponen'!$D$17 -> 98.959 | E20: 37.275 | F20: 0.14362 | G20: 1.0378e-05 | H20: -7.8305e-08 | I20: 2.8872e-11 | J20: 26.31 | K20: 0.77555 | L20: -0.0022271 | M20: 2.6109e-06 | N20: - | O20: - | P20: - | Q20: 45.426 | R20: 561 | S20: 0.342 | T20: -129.7 | U20: gas | V20: =Q20*1000*MAX(0,1-298.15/R20)^S20 -> 35050.912 | W20: =T20*1000 -> -129700 | X20: =T20*1000-V20 -> -164750.91
A21: 16 | B21: TCE | C21: TCE | D21: ='Data Komponen'!$D$18 -> 133.403 | E21: 28.881 | F21: 0.24893 | G21: -0.00017639 | H21: 5.2632e-08 | I21: -3.5668e-12 | J21: 34.934 | K21: 0.85054 | L21: -0.0023306 | M21: 2.6455e-06 | N21: - | O21: - | P21: - | Q21: 46.865 | R21: 602 | S21: 0.294 | T21: -138.49 | U21: gas | V21: =Q21*1000*MAX(0,1-298.15/R21)^S21 -> 38330.905 | W21: =T21*1000 -> -138490 | X21: =T21*1000-V21 -> -176820.9
A22: 17 | B22: HCl | C22: HCl | D22: ='Data Komponen'!$D$19 -> 36.461 | E22: 29.244 | F22: -0.0012615 | G22: 1.121e-06 | H22: 4.9676e-09 | I22: -2.4963e-12 | J22: 73.993 | K22: -0.12946 | L22: -7.898e-05 | M22: 2.6409e-06 | N22: - | O22: - | P22: - | Q22: 30.54 | R22: 324.65 | S22: 0.647 | T22: -92.3 | U22: gas | V22: =Q22*1000*MAX(0,1-298.15/R22)^S22 -> 6037.0301 | W22: =T22*1000 -> -92300 | X22: =T22*1000-V22 -> -98337.03
A23: 18 | B23: FeCl3 | C23: FeCl₃ | D23: ='Data Komponen'!$D$20 -> 162.204 | E23: - | F23: - | G23: - | H23: - | I23: - | J23: - | K23: - | L23: - | M23: - | N23: 35.813 | O23: 0.26813 | P23: -0.00020735 | Q23: - | R23: - | S23: - | T23: -399.5 | U23: padat | V23: - | W23: - | X23: -
A24: 19 | B24: C2H5Cl | C24: C₂H₅Cl | D24: ='Data Komponen'!$D$21 -> 64.515 | E24: 35.946 | F24: 0.052294 | G24: 0.00020321 | H24: -2.2795e-07 | I24: 6.9123e-11 | J24: 60.18 | K24: 0.34553 | L24: -0.0012983 | M24: 2.1963e-06 | N24: - | O24: - | P24: - | Q24: 35.233 | R24: 460.35 | S24: 0.365 | T24: -111.71 | U24: gas | V24: =Q24*1000*MAX(0,1-298.15/R24)^S24 -> 24076.37 | W24: =T24*1000 -> -111710 | X24: =T24*1000-V24 -> -135786.37
A25: 20 | B25: VCM | C25: VCM | D25: ='Data Komponen'!$D$22 -> 62.498 | E25: 17.193 | F25: 0.14564 | G25: -6.4281e-05 | H25: -3.2385e-09 | I25: 6.7882e-12 | J25: 45.366 | K25: 0.28792 | L25: -0.0011535 | M25: 2.1636e-06 | N25: - | O25: - | P25: - | Q25: 35.586 | R25: 432 | S25: 0.483 | T25: 28.45 | U25: gas | V25: =Q25*1000*MAX(0,1-298.15/R25)^S25 -> 20206.784 | W25: =T25*1000 -> 28450 | X25: =T25*1000-V25 -> 8243.216
A26: 21 | B26: HVY | C26: C₄H₈Cl₂ (berat) | D26: ='Data Komponen'!$D$23 -> 127.013 | E26: 0.074 | F26: 0.51333 | G26: -0.00043439 | H26: 2.0527e-07 | I26: -4.1398e-11 | J26: 64.944 | K26: 0.83651 | L26: -0.0021802 | M26: 2.4034e-06 | N26: - | O26: - | P26: - | Q26: 57.353 | R26: 641 | S26: 0.376 | T26: -179 | U26: gas | V26: =Q26*1000*MAX(0,1-298.15/R26)^S26 -> 45329.057 | W26: =T26*1000 -> -179000 | X26: =T26*1000-V26 -> -224329.06
A28: Data tambahan
C29: ΔHf° HCl(aq), pengenceran tak hingga (kJ/mol) = ΔHf° H⁺(aq) + ΔHf° Cl⁻(aq) | D29: -167.08
C30: Tc etilena (K) | D30: 282.36
C31: Pc etilena (bar) | D31: 50.32
C32: Faktor asentrik etilena ω | D32: 0.085
C33: Densitas cair EDC: A (g/mL) | D33: 0.46501
C34: Densitas cair EDC: B | D34: 0.28742
C35: Densitas cair EDC: n | D35: 0.31041
C36: Densitas cair EDC: Tc (K) | D36: 561
C37: Titik didih normal Cl₂ (K) | D37: 239.12
C38: Titik didih normal HCl (K) | D38: 188.15
C39: Titik didih normal EDC (K) | D39: 356.59
C40: Konstanta gas R (kJ/(kmol·K)) | D40: 8.314
A42: Cara menghitung Ĥᵢ (kJ/kmol) di setiap aliran, reference state unsur pada 25 °C dan 1 atm:
A43: Gas: Ĥ = Ĥ°gas,298 + ∫Cp,gas dT dari 298.15 K sampai T.
...

Sheet NME-1 Klorinasi Langsung
A3: Neraca Massa dan Energi
A4: NM Blok 1: Klorinasi Langsung (R-01 + Kondensor Vent)
A5: Tujuan: | B5: Mereaksikan etilena dan klorin menjadi EDC, lalu memisahkan gas vent dari EDC kasar cair
A6: Unjuk Kerja | B6: =1-0.0001 -> 0.9999 | C6: Konversi Cl₂
B7: =300/1000000 -> 0.0003 | C7: Kadar 1,1,2-trikloroetana dalam EDC produk (fraksi berat)
B8: 1.004 | C8: Rasio mol umpan C₂H₄/Cl₂
B9: =200/1000000 -> 0.0002 | C9: Kadar FeCl₃ terlarut dalam EDC (fraksi berat)
B10: =1.08/1000 -> 0.00108 | C10: EDC terbawa gas vent R-01 (kg/kg EDC R-01 + R-02)
B11: 11 | C11: Superheat minimum uap Cl₂ keluar E-101 (K)
A13: Basis Perhitungan | B13: 200000 | C13: t/tahun kapasitas VCM produk
B14: 7920 | C14: jam/tahun waktu operasi
B15: =B13*1000/B14 -> 25252.525 | C15: kg/h target VCM produk
B16: =IFERROR(IF(OR(B16<1,'NME-8 Kolom VCM'!G37<=0),$B$15/4.14,B16*$B$15/'NME-8 Kolom VCM'!G37),$B$15/4.14) -> 6100.5722 | C16: kg/h aliran etilena ke R-01 (dikoreksi iterasi sampai VCM produk = target)
A18: Substance | B18: Inlet | N18: Outlet
B19: Aliran 3 | F19: Aliran 8 | J19: Aliran 10 | N19: Aliran 14 | R19: Aliran 13
B20: ẋᵢ | C20: ṁᵢ (kg/h) | D20: ẏᵢ | E20: ṅᵢ (kmol/h) | F20: ẋᵢ | G20: ṁᵢ (kg/h) | H20: ẏᵢ | I20: ṅᵢ (kmol/h) | J20: ẋᵢ | K20: ṁᵢ (kg/h) | L20: ẏᵢ | M20: ṅᵢ (kmol/h) | N20: ẋᵢ | O20: ṁᵢ (kg/h) | P20: ẏᵢ | Q20: ṅᵢ (kmol/h) | R20: ẋᵢ | S20: ṁᵢ (kg/h) | T20: ẏᵢ | U20: ṅᵢ (kmol/h)
A21: C₂H₄ | B21: =C21/C$42 -> 0 | C21: =E21*'Data Komponen'!$D$3 -> 0 | D21: =E21/E$42 -> 0 | E21: =0 -> 0 | F21: =G21/G$42 -> 0.99975105 | G21: =I21*'Data Komponen'!$D$3 -> 6099.0534 | H21: =I21/I$42 -> 0.99957829 | I21: =$B$16*'T-102'!$X$3/'Data Komponen'!$D$3 -> 217.40406 | J21: =K21/K$42 -> 0 | K21: =M21*'Data Komponen'!$D$3 -> 0 | L21: =M21/M$42 -> 0 | M21: =0 -> 0 | N21: =O21/O$42 -> 0 | O21: =Q21*'Data Komponen'!$D$3 -> 0 | P21: =Q21/Q$42 -> 0 | Q21: =0 -> 0 | R21: =S21/S$42 -> 0.2696025 | S21: =U21*'Data Komponen'!$D$3 -> 26.258047 | T21: =U21/U$42 -> 0.38879451 | U21: =I21-($B$6*E25-Q36) -> 0.93598227
A22: CH₄ | B22: =C22/C$42 -> 0 | C22: =E22*'Data Komponen'!$D$4 -> 0 | D22: =E22/E$42 -> 0 | E22: =0 -> 0 | F22: =G22/G$42 -> 0.00023148056 | G22: =I22*'Data Komponen'!$D$4 -> 1.4121639 | H22: =I22/I$42 -> 0.00040471443 | I22: =$B$16*'T-102'!$X$4/'Data Komponen'!$D$4 -> 0.088023679 | J22: =K22/K$42 -> 0 | K22: =M22*'Data Komponen'!$D$4 -> 0 | L22: =M22/M$42 -> 0 | M22: =0 -> 0 | N22: =O22/O$42 -> 0 | O22: =Q22*'Data Komponen'!$D$4 -> 0 | P22: =Q22/Q$42 -> 0 | Q22: =0 -> 0 | R22: =S22/S$42 -> 0.014499285 | S22: =U22*'Data Komponen'!$D$4 -> 1.4121639 | T22: =U22/U$42 -> 0.036563858 | U22: =I22 -> 0.088023679
A23: C₂H₆ | B23: =C23/C$42 -> 0 | C23: =E23*'Data Komponen'!$D$5 -> 0 | D23: =E23/E$42 -> 0 | E23: =0 -> 0 | F23: =G23/G$42 -> 1.2632146e-05 | G23: =I23*'Data Komponen'!$D$5 -> 0.077063317 | H23: =I23/I$42 -> 1.1783205e-05 | I23: =$B$16*'T-102'!$X$5/'Data Komponen'!$D$5 -> 0.0025627974 | J23: =K23/K$42 -> 0 | K23: =M23*'Data Komponen'!$D$5 -> 0 | L23: =M23/M$42 -> 0 | M23: =0 -> 0 | N23: =O23/O$42 -> 0 | O23: =Q23*'Data Komponen'!$D$5 -> 0 | P23: =Q23/Q$42 -> 0 | Q23: =0 -> 0 | R23: =S23/S$42 -> 0.00079124175 | S23: =U23*'Data Komponen'!$D$5 -> 0.077063317 | T23: =U23/U$42 -> 0.0010645517 | U23: =I23 -> 0.0025627974
A24: C₂H₂ | B24: =C24/C$42 -> 0 | C24: =E24*'Data Komponen'!$D$6 -> 0 | D24: =E24/E$42 -> 0 | E24: =0 -> 0 | F24: =G24/G$42 -> 4.8381901e-06 | G24: =I24*'Data Komponen'!$D$6 -> 0.029515728 | H24: =I24/I$42 -> 5.2118876e-06 | I24: =$B$16*'T-102'!$X$6/'Data Komponen'!$D$6 -> 0.0011335636 | J24: =K24/K$42 -> 0 | K24: =M24*'Data Komponen'!$D$6 -> 0 | L24: =M24/M$42 -> 0 | M24: =0 -> 0 | N24: =O24/O$42 -> 0 | O24: =Q24*'Data Komponen'!$D$6 -> 0 | P24: =Q24/Q$42 -> 0 | Q24: =0 -> 0 | R24: =S24/S$42 -> 0.00030305049 | S24: =U24*'Data Komponen'!$D$6 -> 0.029515728 | T24: =U24/U$42 -> 0.00047086713 | U24: =I24 -> 0.0011335636
A25: Cl₂ | B25: =C25/C$42 -> 0.998471 | C25: =E25*'Data Komponen'!$D$7 -> 15353.62 | D25: =E25/E$42 -> 0.99595193 | E25: =I21/$B$8 -> 216.53791 | F25: =G25/G$42 -> 0 | G25: =I25*'Data Komponen'!$D$7 -> 0 | H25: =I25/I$42 -> 0 | I25: =0 -> 0 | J25: =K25/K$42 -> 0 | K25: =M25*'Data Komponen'!$D$7 -> 0 | L25: =M25/M$42 -> 0 | M25: =0 -> 0 | N25: =O25/O$42 -> 0 | O25: =Q25*'Data Komponen'!$D$7 -> 0 | P25: =Q25/Q$42 -> 0 | Q25: =0 -> 0 | R25: =S25/S$42 -> 0.015764213 | S25: =U25*'Data Komponen'!$D$7 -> 1.535362 | T25: =U25/U$42 -> 0.0089946949 | U25: =E25*(1-$B$6) -> 0.021653791
A26: CₙHₘ | B26: =C26/C$42 -> 4e-06 | C26: =E26*'Data Komponen'!$D$8 -> 0.061508528 | D26: =E26/E$42 -> 1.7634136e-05 | E26: ='T-101'!$B$2/'T-101'!$B$11*C25/'Data Komponen'!$D$8 -> 0.0038339792 | F26: =G26/G$42 -> 0 | G26: =I26*'Data Komponen'!$D$8 -> 0 | H26: =I26/I$42 -> 0 | I26: =0 -> 0 | J26: =K26/K$42 -> 0 | K26: =M26*'Data Komponen'!$D$8 -> 0 | L26: =M26/M$42 -> 0 | M26: =0 -> 0 | N26: =O26/O$42 -> 0 | O26: =Q26*'Data Komponen'!$D$8 -> 0 | P26: =Q26/Q$42 -> 0 | Q26: =0 -> 0 | R26: =S26/S$42 -> 0.00063153413 | S26: =U26*'Data Komponen'!$D$8 -> 0.061508528 | T26: =U26/U$42 -> 0.0015925836 | U26: =E26 -> 0.0038339792
A27: H₂O | B27: =C27/C$42 -> 1.2e-05 | C27: =E27*'Data Komponen'!$D$9 -> 0.18452558 | D27: =E27/E$42 -> 4.7111482e-05 | E27: ='T-101'!$B$3/'T-101'!$B$11*C25/'Data Komponen'!$D$9 -> 0.010242886 | F27: =G27/G$42 -> 0 | G27: =I27*'Data Komponen'!$D$9 -> 0 | H27: =I27/I$42 -> 0 | I27: =0 -> 0 | J27: =K27/K$42 -> 0 | K27: =M27*'Data Komponen'!$D$9 -> 0 | L27: =M27/M$42 -> 0 | M27: =0 -> 0 | N27: =O27/O$42 -> 8.6289026e-06 | O27: =Q27*'Data Komponen'!$D$9 -> 0.18452558 | P27: =Q27/Q$42 -> 4.7406553e-05 | Q27: =E27 -> 0.010242886 | R27: =S27/S$42 -> 0 | S27: =U27*'Data Komponen'!$D$9 -> 0 | T27: =U27/U$42 -> 0 | U27: =0 -> 0
A28: CₓHᵧCl | B28: =C28/C$42 -> 8e-06 | C28: =E28*'Data Komponen'!$D$10 -> 0.12301706 | D28: =E28/E$42 -> 1.12068e-05 | E28: ='T-101'!$B$4/'T-101'!$B$11*C25/'Data Komponen'!$D$10 -> 0.0024365603 | F28: =G28/G$42 -> 0 | G28: =I28*'Data Komponen'!$D$10 -> 0 | H28: =I28/I$42 -> 0 | I28: =0 -> 0 | J28: =K28/K$42 -> 0 | K28: =M28*'Data Komponen'!$D$10 -> 0 | L28: =M28/M$42 -> 0 | M28: =0 -> 0 | N28: =O28/O$42 -> 0 | O28: =Q28*'Data Komponen'!$D$10 -> 0 | P28: =Q28/Q$42 -> 0 | Q28: =0 -> 0 | R28: =S28/S$42 -> 0.0012630683 | S28: =U28*'Data Komponen'!$D$10 -> 0.12301706 | T28: =U28/U$42 -> 0.0010121145 | U28: =E28 -> 0.0024365603
A29: Br₂ | B29: =C29/C$42 -> 9e-05 | C29: =E29*'Data Komponen'!$D$11 -> 1.3839419 | D29: =E29/E$42 -> 3.9831235e-05 | E29: ='T-101'!$B$5/'T-101'!$B$11*C25/'Data Komponen'!$D$11 -> 0.0086600287 | F29: =G29/G$42 -> 0 | G29: =I29*'Data Komponen'!$D$11 -> 0 | H29: =I29/I$42 -> 0 | I29: =0 -> 0 | J29: =K29/K$42 -> 0 | K29: =M29*'Data Komponen'!$D$11 -> 0 | L29: =M29/M$42 -> 0 | M29: =0 -> 0 | N29: =O29/O$42 -> 6.4716769e-05 | O29: =Q29*'Data Komponen'!$D$11 -> 1.3839419 | P29: =Q29/Q$42 -> 4.0080709e-05 | Q29: =E29 -> 0.0086600287 | R29: =S29/S$42 -> 0 | S29: =U29*'Data Komponen'!$D$11 -> 0 | T29: =U29/U$42 -> 0 | U29: =0 -> 0
A30: NCl₃ | B30: =C30/C$42 -> 5e-06 | C30: =E30*'Data Komponen'!$D$12 -> 0.076885659 | D30: =E30/E$42 -> 2.937985e-06 | E30: ='T-101'!$B$6/'T-101'!$B$11*C25/'Data Komponen'!$D$12 -> 0.0006387709 | F30: =G30/G$42 -> 0 | G30: =I30*'Data Komponen'!$D$12 -> 0 | H30: =I30/I$42 -> 0 | I30: =0 -> 0 | J30: =K30/K$42 -> 0 | K30: =M30*'Data Komponen'!$D$12 -> 0 | L30: =M30/M$42 -> 0 | M30: =0 -> 0 | N30: =O30/O$42 -> 3.5953761e-06 | O30: =Q30*'Data Komponen'!$D$12 -> 0.076885659 | P30: =Q30/Q$42 -> 2.9563863e-06 | Q30: =E30 -> 0.0006387709 | R30: =S30/S$42 -> 0 | S30: =U30*'Data Komponen'!$D$12 -> 0 | T30: =U30/U$42 -> 0 | U30: =0 -> 0
A31: H₂ | B31: =C31/C$42 -> 3e-05 | C31: =E31*'Data Komponen'!$D$13 -> 0.46131396 | D31: =E31/E$42 -> 0.0010524719 | E31: ='T-101'!$B$7/'T-101'!$B$11*C25/'Data Komponen'!$D$13 -> 0.22882637 | F31: =G31/G$42 -> 0 | G31: =I31*'Data Komponen'!$D$13 -> 0 | H31: =I31/I$42 -> 0 | I31: =0 -> 0 | J31: =K31/K$42 -> 0 | K31: =M31*'Data Komponen'!$D$13 -> 0 | L31: =M31/M$42 -> 0 | M31: =0 -> 0 | N31: =O31/O$42 -> 0 | O31: =Q31*'Data Komponen'!$D$13 -> 0 | P31: =Q31/Q$42 -> 0 | Q31: =0 -> 0 | R31: =S31/S$42 -> 0.004736506 | S31: =U31*'Data Komponen'!$D$13 -> 0.46131396 | T31: =U31/U$42 -> 0.095051411 | U31: =E31 -> 0.22882637
A32: O₂ | B32: =C32/C$42 -> 0.00018 | C32: =E32*'Data Komponen'!$D$14 -> 2.7678837 | D32: =E32/E$42 -> 0.00039784681 | E32: ='T-101'!$B$8/'T-101'!$B$11*C25/'Data Komponen'!$D$14 -> 0.08649907 | F32: =G32/G$42 -> 0 | G32: =I32*'Data Komponen'!$D$14 -> 0 | H32: =I32/I$42 -> 0 | I32: =0 -> 0 | J32: =K32/K$42 -> 0 | K32: =M32*'Data Komponen'!$D$14 -> 0 | L32: =M32/M$42 -> 0 | M32: =0 -> 0 | N32: =O32/O$42 -> 0 | O32: =Q32*'Data Komponen'!$D$14 -> 0 | P32: =Q32/Q$42 -> 0 | Q32: =0 -> 0 | R32: =S32/S$42 -> 0.028419036 | S32: =U32*'Data Komponen'!$D$14 -> 2.7678837 | T32: =U32/U$42 -> 0.035930556 | U32: =E32 -> 0.08649907
A33: N₂ | B33: =C33/C$42 -> 0.0006 | C33: =E33*'Data Komponen'!$D$15 -> 9.2262791 | D33: =E33/E$42 -> 0.0015148021 | E33: ='T-101'!$B$9/'T-101'!$B$11*C25/'Data Komponen'!$D$15 -> 0.3293453 | F33: =G33/G$42 -> 0 | G33: =I33*'Data Komponen'!$D$15 -> 0 | H33: =I33/I$42 -> 0 | I33: =0 -> 0 | J33: =K33/K$42 -> 0 | K33: =M33*'Data Komponen'!$D$15 -> 0 | L33: =M33/M$42 -> 0 | M33: =0 -> 0 | N33: =O33/O$42 -> 0 | O33: =Q33*'Data Komponen'!$D$15 -> 0 | P33: =Q33/Q$42 -> 0 | Q33: =0 -> 0 | R33: =S33/S$42 -> 0.094730119 | S33: =U33*'Data Komponen'!$D$15 -> 9.2262791 | T33: =U33/U$42 -> 0.13680563 | U33: =E33 -> 0.3293453
A34: CO₂ | B34: =C34/C$42 -> 0.0006 | C34: =E34*'Data Komponen'!$D$16 -> 9.2262791 | D34: =E34/E$42 -> 0.00096422784 | E34: ='T-101'!$B$10/'T-101'!$B$11*C25/'Data Komponen'!$D$16 -> 0.20964052 | F34: =G34/G$42 -> 0 | G34: =I34*'Data Komponen'!$D$16 -> 0 | H34: =I34/I$42 -> 0 | I34: =0 -> 0 | J34: =K34/K$42 -> 0 | K34: =M34*'Data Komponen'!$D$16 -> 0 | L34: =M34/M$42 -> 0 | M34: =0 -> 0 | N34: =O34/O$42 -> 0 | O34: =Q34*'Data Komponen'!$D$16 -> 0 | P34: =Q34/Q$42 -> 0 | Q34: =0 -> 0 | R34: =S34/S$42 -> 0.094730119 | S34: =U34*'Data Komponen'!$D$16 -> 9.2262791 | T34: =U34/U$42 -> 0.087081865 | U34: =E34 -> 0.20964052
A35: EDC | B35: =C35/C$42 -> 0 | C35: =E35*'Data Komponen'!$D$17 -> 0 | D35: =E35/E$42 -> 0 | E35: =0 -> 0 | F35: =G35/G$42 -> 0 | G35: =I35*'Data Komponen'!$D$17 -> 0 | H35: =I35/I$42 -> 0 | I35: =0 -> 0 | J35: =K35/K$42 -> 0 | K35: =M35*'Data Komponen'!$D$17 -> 0 | L35: =M35/M$42 -> 0 | M35: =0 -> 0 | N35: =O35/O$42 -> 0.9994221 | O35: =Q35*'Data Komponen'!$D$17 -> 21372.236 | P35: =Q35/Q$42 -> 0.99956429 | Q35: =$B$6*E25-2*Q36-U35 -> 215.97062 | R35: =S35/S$42 -> 0.45649382 | S35: =U35*'Data Komponen'!$D$17 -> 44.460404 | T35: =U35/U$42 -> 0.18662534 | U35: =$B$10*(($B$6*E25-2*Q36)+'NME-2 Oksiklorinasi'!Q34) -> 0.44928105
A36: TCE | B36: =C36/C$42 -> 0 | C36: =E36*'Data Komponen'!$D$18 -> 0 | D36: =E36/E$42 -> 0 | E36: =0 -> 0 | F36: =G36/G$42 -> 0 | G36: =I36*'Data Komponen'!$D$18 -> 0 | H36: =I36/I$42 -> 0 | I36: =0 -> 0 | J36: =K36/K$42 -> 0 | K36: =M36*'Data Komponen'!$D$18 -> 0 | L36: =M36/M$42 -> 0 | M36: =0 -> 0 | N36: =O36/O$42 -> 0.00030054052 | O36: =Q36*'Data Komponen'!$D$18 -> 6.4269371 | P36: =Q36/Q$42 -> 0.00022297415 | Q36: =$B$7*$B$6*E25*'Data Komponen'!$D$17/('Data Komponen'!$D$18*(1-$B$7)+2*$B$7*'Data Komponen'!$D$17) -> 0.048176856 | R36: =S36/S$42 -> 0 | S36: =U36*'Data Komponen'!$D$18 -> 0 | T36: =U36/U$42 -> 0 | U36: =0 -> 0
A37: HCl | B37: =C37/C$42 -> 0 | C37: =E37*'Data Komponen'!$D$19 -> 0 | D37: =E37/E$42 -> 0 | E37: =0 -> 0 | F37: =G37/G$42 -> 0 | G37: =I37*'Data Komponen'!$D$19 -> 0 | H37: =I37/I$42 -> 0 | I37: =0 -> 0 | J37: =K37/K$42 -> 0 | K37: =M37*'Data Komponen'!$D$19 -> 0 | L37: =M37/M$42 -> 0 | M37: =0 -> 0 | N37: =O37/O$42 -> 0 | O37: =Q37*'Data Komponen'!$D$19 -> 0 | P37: =Q37/Q$42 -> 0 | Q37: =0 -> 0 | R37: =S37/S$42 -> 0.018035514 | S37: =U37*'Data Komponen'!$D$19 -> 1.7565763 | T37: =U37/U$42 -> 0.020012021 | U37: =Q36 -> 0.048176856
A38: FeCl₃ | B38: =C38/C$42 -> 0 | C38: =E38*'Data Komponen'!$D$20 -> 0 | D38: =E38/E$42 -> 0 | E38: =0 -> 0 | F38: =G38/G$42 -> 0 | G38: =I38*'Data Komponen'!$D$20 -> 0 | H38: =I38/I$42 -> 0 | I38: =0 -> 0 | J38: =K38/K$42 -> 1 | K38: =M38*'Data Komponen'!$D$20 -> 4.285811 | L38: =M38/M$42 -> 1 | M38: =$B$9/(1-$B$9)*((Q35+U35)*'Data Komponen'!$D$17+Q36*'Data Komponen'!$D$18+Q27*'Data Komponen'!$D$9+Q29*'Data Komponen'!$D$11+Q30*'Data Komponen'!$D$12)/'Data Komponen'!$D$20 -> 0.026422351 | N38: =O38/O$42 -> 0.00020041582 | O38: =Q38*'Data Komponen'!$D$20 -> 4.285811 | P38: =Q38/Q$42 -> 0.00012228903 | Q38: =M38 -> 0.026422351 | R38: =S38/S$42 -> 0 | S38: =U38*'Data Komponen'!$D$20 -> 0 | T38: =U38/U$42 -> 0 | U38: =0 -> 0
A39: C₂H₅Cl | B39: =C39/C$42 -> 0 | C39: =E39*'Data Komponen'!$D$21 -> 0 | D39: =E39/E$42 -> 0 | E39: =0 -> 0 | F39: =G39/G$42 -> 0 | G39: =I39*'Data Komponen'!$D$21 -> 0 | H39: =I39/I$42 -> 0 | I39: =0 -> 0 | J39: =K39/K$42 -> 0 | K39: =M39*'Data Komponen'!$D$21 -> 0 | L39: =M39/M$42 -> 0 | M39: =0 -> 0 | N39: =O39/O$42 -> 0 | O39: =Q39*'Data Komponen'!$D$21 -> 0 | P39: =Q39/Q$42 -> 0 | Q39: =0 -> 0 | R39: =S39/S$42 -> 0 | S39: =U39*'Data Komponen'!$D$21 -> 0 | T39: =U39/U$42 -> 0 | U39: =0 -> 0
A40: VCM | B40: =C40/C$42 -> 0 | C40: =E40*'Data Komponen'!$D$22 -> 0 | D40: =E40/E$42 -> 0 | E40: =0 -> 0 | F40: =G40/G$42 -> 0 | G40: =I40*'Data Komponen'!$D$22 -> 0 | H40: =I40/I$42 -> 0 | I40: =0 -> 0 | J40: =K40/K$42 -> 0 | K40: =M40*'Data Komponen'!$D$22 -> 0 | L40: =M40/M$42 -> 0 | M40: =0 -> 0 | N40: =O40/O$42 -> 0 | O40: =Q40*'Data Komponen'!$D$22 -> 0 | P40: =Q40/Q$42 -> 0 | Q40: =0 -> 0 | R40: =S40/S$42 -> 0 | S40: =U40*'Data Komponen'!$D$22 -> 0 | T40: =U40/U$42 -> 0 | U40: =0 -> 0
A41: C₄H₈Cl₂ (berat) | B41: =C41/C$42 -> 0 | C41: =E41*'Data Komponen'!$D$23 -> 0 | D41: =E41/E$42 -> 0 | E41: =0 -> 0 | F41: =G41/G$42 -> 0 | G41: =I41*'Data Komponen'!$D$23 -> 0 | H41: =I41/I$42 -> 0 | I41: =0 -> 0 | J41: =K41/K$42 -> 0 | K41: =M41*'Data Komponen'!$D$23 -> 0 | L41: =M41/M$42 -> 0 | M41: =0 -> 0 | N41: =O41/O$42 -> 0 | O41: =Q41*'Data Komponen'!$D$23 -> 0 | P41: =Q41/Q$42 -> 0 | Q41: =0 -> 0 | R41: =S41/S$42 -> 0 | S41: =U41*'Data Komponen'!$D$23 -> 0 | T41: =U41/U$42 -> 0 | U41: =0 -> 0
A42: Sub Total | B42: =SUM(B21:B41) -> 1 | C42: =SUM(C21:C41) -> 15377.132 | D42: =SUM(D21:D41) -> 1 | E42: =SUM(E21:E41) -> 217.41803 | F42: =SUM(F21:F41) -> 1 | G42: =SUM(G21:G41) -> 6100.5722 | H42: =SUM(H21:H41) -> 1 | I42: =SUM(I21:I41) -> 217.49578 | ... U42: =SUM(U21:U41) -> 2.4073958
A43: TOTAL MASSA | B43: =C42+G42+K42 -> 21481.99 | N43: =O42+S42 -> 21481.99
A44: Selisih (Inlet − Outlet), kg/h | B44: =B43-N43 -> -1.6734703e-10
...

Sheet NME-2 Oksiklorinasi
A3: Neraca Massa dan Energi
A4: NM Blok 2: Oksiklorinasi (R-02)
A5: Tujuan: | B5: Mereaksikan etilena, HCl daur ulang, dan oksigen (udara) menjadi EDC
A6: Unjuk Kerja | B6: 2 | C6: Rasio mol HCl/C₂H₄
B7: 0.8 | C7: Rasio mol O₂/C₂H₄
B8: 0.995 | C8: Konversi C₂H₄
B9: 0.982 | C9: Efisiensi C₂H₄ menjadi EDC (mol EDC/mol C₂H₄ umpan)
B10: 0.986 | C10: Konversi HCl
B11: 0.21 | C11: Fraksi mol O₂ dalam udara
B12: 0.75 | C12: Efisiensi isentropik kompresor K-101
B13: 11 | C13: Superheat uap HCl keluar E-109 (K)
A15: Basis Perhitungan | B15: ='NME-1 Klorinasi Langsung'!$B$16 -> 6100.5722 | C15: kg/h aliran etilena ke R-01 (NME-1)
A17: Substance | B17: Inlet | N17: Outlet
B18: Aliran 9 | F18: Aliran 44 | J18: Aliran 17 | N18: Aliran 18
B19: ẋᵢ | C19: ṁᵢ (kg/h) | D19: ẏᵢ | E19: ṅᵢ (kmol/h) | F19: ẋᵢ | G19: ṁᵢ (kg/h) | H19: ẏᵢ | I19: ṅᵢ (kmol/h) | J19: ẋᵢ | K19: ṁᵢ (kg/h) | L19: ẏᵢ | M19: ṅᵢ (kmol/h) | N19: ẋᵢ | O19: ṁᵢ (kg/h) | P19: ẏᵢ | Q19: ṅᵢ (kmol/h)
A20: C₂H₄ | B20: =C20/C$41 -> 0.99975105 | C20: =E20*'Data Komponen'!$D$3 -> 5701.6777 | D20: =E20/E$41 -> 0.99957829 | E20: =I36/$B$6 -> 203.23939 | F20: =G20/G$41 -> 0 | G20: =I20*'Data Komponen'!$D$3 -> 0 | H20: =I20/I$41 -> 0 | I20: ='NME-7 Kolom HCl'!I15 -> 0 | J20: =K20/K$41 -> 0 | K20: =M20*'Data Komponen'!$D$3 -> 0 | L20: =M20/M$41 -> 0 | M20: =0 -> 0 | N20: =O20/O$41 -> 0.00066170751 | O20: =Q20*'Data Komponen'!$D$3 -> 28.508389 | P20: =Q20/Q$41 -> 0.00093556297 | Q20: =E20*(1-$B$8) -> 1.0161969
A21: CH₄ | B21: =C21/C$41 -> 0.00023148056 | C21: =E21*'Data Komponen'!$D$4 -> 1.3201562 | D21: =E21/E$41 -> 0.00040471443 | E21: =(E20*'Data Komponen'!$D$3/'T-102'!$X$3)*'T-102'!$X$4/'Data Komponen'!$D$4 -> 0.082288614 | F21: =G21/G$41 -> 0 | G21: =I21*'Data Komponen'!$D$4 -> 0 | H21: =I21/I$41 -> 0 | I21: ='NME-7 Kolom HCl'!I16 -> 0 | J21: =K21/K$41 -> 0 | K21: =M21*'Data Komponen'!$D$4 -> 0 | L21: =M21/M$41 -> 0 | M21: =0 -> 0 | N21: =O21/O$41 -> 3.0642114e-05 | O21: =Q21*'Data Komponen'!$D$4 -> 1.3201562 | P21: =Q21/Q$41 -> 7.5759115e-05 | Q21: =E21+I21+M21 -> 0.082288614
A22: C₂H₆ | B22: =C22/C$41 -> 1.2632146e-05 | C22: =E22*'Data Komponen'!$D$5 -> 0.072042359 | D22: =E22/E$41 -> 1.1783205e-05 | E22: =(E20*'Data Komponen'!$D$3/'T-102'!$X$3)*'T-102'!$X$5/'Data Komponen'!$D$5 -> 0.0023958217 | F22: =G22/G$41 -> 0 | G22: =I22*'Data Komponen'!$D$5 -> 0 | H22: =I22/I$41 -> 0 | I22: ='NME-7 Kolom HCl'!I17 -> 0 | J22: =K22/K$41 -> 0 | K22: =M22*'Data Komponen'!$D$5 -> 0 | L22: =M22/M$41 -> 0 | M22: =0 -> 0 | N22: =O22/O$41 -> 1.6721734e-06 | O22: =Q22*'Data Komponen'!$D$5 -> 0.072042359 | P22: =Q22/Q$41 -> 2.2057163e-06 | Q22: =E22+I22+M22 -> 0.0023958217
A23: C₂H₂ | B23: =C23/C$41 -> 4.8381901e-06 | C23: =E23*'Data Komponen'!$D$6 -> 0.02759267 | D23: =E23/E$41 -> 5.2118876e-06 | E23: =(E20*'Data Komponen'!$D$3/'T-102'!$X$3)*'T-102'!$X$6/'Data Komponen'!$D$6 -> 0.0010597077 | F23: =G23/G$41 -> 0 | G23: =I23*'Data Komponen'!$D$6 -> 0 | H23: =I23/I$41 -> 0 | I23: ='NME-7 Kolom HCl'!I18 -> 0 | J23: =K23/K$41 -> 0 | K23: =M23*'Data Komponen'!$D$6 -> 0 | L23: =M23/M$41 -> 0 | M23: =0 -> 0 | N23: =O23/O$41 -> 6.4045279e-07 | O23: =Q23*'Data Komponen'!$D$6 -> 0.02759267 | P23: =Q23/Q$41 -> 9.7562125e-07 | Q23: =E23+I23+M23 -> 0.0010597077
A24: Cl₂ | B24: =C24/C$41 -> 0 | C24: =E24*'Data Komponen'!$D$7 -> 0 | D24: =E24/E$41 -> 0 | E24: =0 -> 0 | F24: =G24/G$41 -> 0.014588688 | G24: =I24*'Data Komponen'!$D$7 -> 219.4523 | H24: =I24/I$41 -> 0.0075559258 | I24: ='NME-7 Kolom HCl'!I19 -> 3.0950187 | J24: =K24/K$41 -> 0 | K24: =M24*'Data Komponen'!$D$7 -> 0 | L24: =M24/M$41 -> 0 | M24: =0 -> 0 | N24: =O24/O$41 -> 0.0050937019 | O24: =Q24*'Data Komponen'!$D$7 -> 219.4523 | P24: =Q24/Q$41 -> 0.0028494328 | Q24: =E24+I24+M24 -> 3.0950187
A25: CₙHₘ | B25: =C25/C$41 -> 0 | C25: =E25*'Data Komponen'!$D$8 -> 0 | D25: =E25/E$41 -> 0 | E25: =0 -> 0 | F25: =G25/G$41 -> 0 | G25: =I25*'Data Komponen'!$D$8 -> 0 | H25: =I25/I$41 -> 0 | I25: ='NME-7 Kolom HCl'!I20 -> 0 | J25: =K25/K$41 -> 0 | K25: =M25*'Data Komponen'!$D$8 -> 0 | L25: =M25/M$41 -> 0 | M25: =0 -> 0 | N25: =O25/O$41 -> 0 | O25: =Q25*'Data Komponen'!$D$8 -> 0 | P25: =Q25/Q$41 -> 0 | Q25: =0 -> 0
A26: H₂O | B26: =C26/C$41 -> 0 | C26: =E26*'Data Komponen'!$D$9 -> 0 | D26: =E26/E$41 -> 0 | E26: =0 -> 0 | F26: =G26/G$41 -> 0 | G26: =I26*'Data Komponen'!$D$9 -> 0 | H26: =I26/I$41 -> 0 | I26: ='NME-7 Kolom HCl'!I21 -> 0 | J26: =K26/K$41 -> 0 | K26: =M26*'Data Komponen'!$D$9 -> 0 | L26: =M26/M$41 -> 0 | M26: =0 -> 0 | N26: =O26/O$41 -> 0.084303811 | O26: =Q26*'Data Komponen'!$D$9 -> 3632.0667 | P26: =Q26/Q$41 -> 0.18561569 | Q26: =Q34+Q33 -> 201.61347
A27: CₓHᵧCl | B27: =C27/C$41 -> 0 | C27: =E27*'Data Komponen'!$D$10 -> 0 | D27: =E27/E$41 -> 0 | E27: =0 -> 0 | F27: =G27/G$41 -> 0 | G27: =I27*'Data Komponen'!$D$10 -> 0 | H27: =I27/I$41 -> 0 | I27: ='NME-7 Kolom HCl'!I22 -> 0 | J27: =K27/K$41 -> 0 | K27: =M27*'Data Komponen'!$D$10 -> 0 | L27: =M27/M$41 -> 0 | M27: =0 -> 0 | N27: =O27/O$41 -> 0 | O27: =Q27*'Data Komponen'!$D$10 -> 0 | P27: =Q27/Q$41 -> 0 | Q27: =0 -> 0
A28: Br₂ | B28: =C28/C$41 -> 0 | C28: =E28*'Data Komponen'!$D$11 -> 0 | D28: =E28/E$41 -> 0 | E28: =0 -> 0 | F28: =G28/G$41 -> 0 | G28: =I28*'Data Komponen'!$D$11 -> 0 | H28: =I28/I$41 -> 0 | I28: ='NME-7 Kolom HCl'!I23 -> 0 | J28: =K28/K$41 -> 0 | K28: =M28*'Data Komponen'!$D$11 -> 0 | L28: =M28/M$41 -> 0 | M28: =0 -> 0 | N28: =O28/O$41 -> 0 | O28: =Q28*'Data Komponen'!$D$11 -> 0 | P28: =Q28/Q$41 -> 0 | Q28: =0 -> 0
A29: NCl₃ | B29: =C29/C$41 -> 0 | C29: =E29*'Data Komponen'!$D$12 -> 0 | D29: =E29/E$41 -> 0 | E29: =0 -> 0 | F29: =G29/G$41 -> 0 | G29: =I29*'Data Komponen'!$D$12 -> 0 | H29: =I29/I$41 -> 0 | I29: ='NME-7 Kolom HCl'!I24 -> 0 | J29: =K29/K$41 -> 0 | K29: =M29*'Data Komponen'!$D$12 -> 0 | L29: =M29/M$41 -> 0 | M29: =0 -> 0 | N29: =O29/O$41 -> 0 | O29: =Q29*'Data Komponen'!$D$12 -> 0 | P29: =Q29/Q$41 -> 0 | Q29: =0 -> 0
A30: H₂ | B30: =C30/C$41 -> 0 | C30: =E30*'Data Komponen'!$D$13 -> 0 | D30: =E30/E$41 -> 0 | E30: =0 -> 0 | F30: =G30/G$41 -> 0 | G30: =I30*'Data Komponen'!$D$13 -> 0 | H30: =I30/I$41 -> 0 | I30: ='NME-7 Kolom HCl'!I25 -> 0 | J30: =K30/K$41 -> 0 | K30: =M30*'Data Komponen'!$D$13 -> 0 | L30: =M30/M$41 -> 0 | M30: =0 -> 0 | N30: =O30/O$41 -> 0 | O30: =Q30*'Data Komponen'!$D$13 -> 0 | P30: =Q30/Q$41 -> 0 | Q30: =0 -> 0
A31: O₂ | B31: =C31/C$41 -> 0 | C31: =E31*'Data Komponen'!$D$14 -> 0 | D31: =E31/E$41 -> 0 | E31: =0 -> 0 | F31: =G31/G$41 -> 0 | G31: =I31*'Data Komponen'!$D$14 -> 0 | H31: =I31/I$41 -> 0 | I31: ='NME-7 Kolom HCl'!I26 -> 0 | J31: =K31/K$41 -> 0.2329148 | K31: =M31*'Data Komponen'!$D$14 -> 5202.7657 | L31: =M31/M$41 -> 0.21 | M31: =$B$7*E20 -> 162.59151 | N31: =O31/O$41 -> 0.044379766 | O31: =Q31*'Data Komponen'!$D$14 -> 1912.0164 | P31: =Q31/Q$41 -> 0.055011103 | Q31: =M31-0.5*Q34-1.5*Q33 -> 59.75238
A32: N₂ | B32: =C32/C$41 -> 0 | C32: =E32*'Data Komponen'!$D$15 -> 0 | D32: =E32/E$41 -> 0 | E32: =0 -> 0 | F32: =G32/G$41 -> 0 | G32: =I32*'Data Komponen'!$D$15 -> 0 | H32: =I32/I$41 -> 0 | I32: ='NME-7 Kolom HCl'!I27 -> 0 | J32: =K32/K$41 -> 0.7670852 | K32: =M32*'Data Komponen'!$D$15 -> 17134.869 | L32: =M32/M$41 -> 0.79 | M32: =M31*(1-$B$11)/$B$11 -> 611.65377 | N32: =O32/O$41 -> 0.39771702 | O32: =Q32*'Data Komponen'!$D$15 -> 17134.869 | P32: =Q32/Q$41 -> 0.56311981 | Q32: =E32+I32+M32 -> 611.65377
A33: CO₂ | B33: =C33/C$41 -> 0 | C33: =E33*'Data Komponen'!$D$16 -> 0 | D33: =E33/E$41 -> 0 | E33: =0 -> 0 | F33: =G33/G$41 -> 0 | G33: =I33*'Data Komponen'!$D$16 -> 0 | H33: =I33/I$41 -> 0 | I33: ='NME-7 Kolom HCl'!I28 -> 0 | J33: =K33/K$41 -> 0 | K33: =M33*'Data Komponen'!$D$16 -> 0 | L33: =M33/M$41 -> 0 | M33: =0 -> 0 | N33: =O33/O$41 -> 0.0020761209 | O33: =Q33*'Data Komponen'!$D$16 -> 89.445654 | P33: =Q33/Q$41 -> 0.0018711259 | Q33: =2*($B$8*E20-Q34-Q38) -> 2.0323939
A34: EDC | B34: =C34/C$41 -> 0 | C34: =E34*'Data Komponen'!$D$17 -> 0 | D34: =E34/E$41 -> 0 | E34: =0 -> 0 | F34: =G34/G$41 -> 0 | G34: =I34*'Data Komponen'!$D$17 -> 0 | H34: =I34/I$41 -> 0 | I34: ='NME-7 Kolom HCl'!I29 -> 0 | J34: =K34/K$41 -> 0 | K34: =M34*'Data Komponen'!$D$17 -> 0 | L34: =M34/M$41 -> 0 | M34: =0 -> 0 | N34: =O34/O$41 -> 0.45842475 | O34: =Q34*'Data Komponen'!$D$17 -> 19750.344 | P34: =Q34/Q$41 -> 0.18374457 | Q34: =$B$9*E20 -> 199.58108
A35: TCE | B35: =C35/C$41 -> 0 | C35: =E35*'Data Komponen'!$D$18 -> 0 | D35: =E35/E$41 -> 0 | E35: =0 -> 0 | F35: =G35/G$41 -> 0 | G35: =I35*'Data Komponen'!$D$18 -> 0 | H35: =I35/I$41 -> 0 | I35: ='NME-7 Kolom HCl'!I30 -> 0 | J35: =K35/K$41 -> 0 | K35: =M35*'Data Komponen'!$D$18 -> 0 | L35: =M35/M$41 -> 0 | M35: =0 -> 0 | N35: =O35/O$41 -> 0 | O35: =Q35*'Data Komponen'!$D$18 -> 0 | P35: =Q35/Q$41 -> 0 | Q35: =0 -> 0
A36: HCl | B36: =C36/C$41 -> 0 | C36: =E36*'Data Komponen'!$D$19 -> 0 | D36: =E36/E$41 -> 0 | E36: =0 -> 0 | F36: =G36/G$41 -> 0.98524113 | G36: =I36*'Data Komponen'!$D$19 -> 14820.623 | H36: =I36/I$41 -> 0.99234407 | I36: ='NME-7 Kolom HCl'!I31 -> 406.47877 | J36: =K36/K$41 -> 0 | K36: =M36*'Data Komponen'!$D$19 -> 0 | L36: =M36/M$41 -> 0 | M36: =0 -> 0 | N36: =O36/O$41 -> 0.0048160155 | O36: =Q36*'Data Komponen'!$D$19 -> 207.48872 | P36: =Q36/Q$41 -> 0.0052391526 | Q36: =I36*(1-$B$10) -> 5.6907028
A37: FeCl₃ | B37: =C37/C$41 -> 0 | C37: =E37*'Data Komponen'!$D$20 -> 0 | D37: =E37/E$41 -> 0 | E37: =0 -> 0 | F37: =G37/G$41 -> 0 | G37: =I37*'Data Komponen'!$D$20 -> 0 | H37: =I37/I$41 -> 0 | I37: ='NME-7 Kolom HCl'!I32 -> 0 | J37: =K37/K$41 -> 0 | K37: =M37*'Data Komponen'!$D$20 -> 0 | L37: =M37/M$41 -> 0 | M37: =0 -> 0 | N37: =O37/O$41 -> 0 | O37: =Q37*'Data Komponen'!$D$20 -> 0 | P37: =Q37/Q$41 -> 0 | Q37: =0 -> 0
A38: C₂H₅Cl | B38: =C38/C$41 -> 0 | C38: =E38*'Data Komponen'!$D$21 -> 0 | D38: =E38/E$41 -> 0 | E38: =0 -> 0 | F38: =G38/G$41 -> 0 | G38: =I38*'Data Komponen'!$D$21 -> 0 | H38: =I38/I$41 -> 0 | I38: ='NME-7 Kolom HCl'!I33 -> 0 | J38: =K38/K$41 -> 0 | K38: =M38*'Data Komponen'!$D$21 -> 0 | L38: =M38/M$41 -> 0 | M38: =0 -> 0 | N38: =O38/O$41 -> 0.0024347364 | O38: =Q38*'Data Komponen'!$D$21 -> 104.89591 | P38: =Q38/Q$41 -> 0.0014969008 | Q38: =$B$10*I36-2*Q34 -> 1.6259151
A39: VCM | B39: =C39/C$41 -> 0 | C39: =E39*'Data Komponen'!$D$22 -> 0 | D39: =E39/E$41 -> 0 | E39: =0 -> 0 | F39: =G39/G$41 -> 0.00017018364 | G39: =I39*'Data Komponen'!$D$22 -> 2.5600103 | H39: =I39/I$41 -> 0.0001 | I39: ='NME-7 Kolom HCl'!I34 -> 0.040961475 | J39: =K39/K$41 -> 0 | K39: =M39*'Data Komponen'!$D$22 -> 0 | L39: =M39/M$41 -> 0 | M39: =0 -> 0 | N39: =O39/O$41 -> 5.9420336e-05 | O39: =Q39*'Data Komponen'!$D$22 -> 2.5600103 | P39: =Q39/Q$41 -> 3.7711233e-05 | Q39: =E39+I39+M39 -> 0.040961475
A40: C₄H₈Cl₂ (berat) | B40: =C40/C$41 -> 0 | C40: =E40*'Data Komponen'!$D$23 -> 0 | D40: =E40/E$41 -> 0 | E40: =0 -> 0 | F40: =G40/G$41 -> 0 | G40: =I40*'Data Komponen'!$D$23 -> 0 | H40: =I40/I$41 -> 0 | I40: ='NME-7 Kolom HCl'!I35 -> 0 | J40: =K40/K$41 -> 0 | K40: =M40*'Data Komponen'!$D$23 -> 0 | L40: =M40/M$41 -> 0 | M40: =0 -> 0 | N40: =O40/O$41 -> 0 | O40: =Q40*'Data Komponen'!$D$23 -> 0 | P40: =Q40/Q$41 -> 0 | Q40: =0 -> 0
A41: Sub Total | B41: =SUM(B20:B40) -> 1 | C41: =SUM(C20:C40) -> 5703.0975 | D41: =SUM(D20:D40) -> 1 | E41: =SUM(E20:E40) -> 203.32513 | F41: =SUM(F20:F40) -> 1 | G41: =SUM(G20:G40) -> 15042.635 | H41: =SUM(H20:H40) -> 1 | I41: =SUM(I20:I40) -> 409.61475 | ... Q41: =SUM(Q20:Q40) -> 1086.1876
A42: TOTAL MASSA | B42: =C41+G41+K41 -> 43083.367 | N42: =O41 -> 43083.066
A43: Selisih (Inlet − Outlet), kg/h | B43: =B42-N42 -> 0.30038781
A46: Neraca Energi K-101: Kompresor udara
...

Sheet NME-3 Kondensasi-Dekantasi
A3: Neraca Massa dan Energi
A4: NM Blok 3: Kondensasi & Dekantasi EDC Kasar
A5: Tujuan: | B5: Mengembunkan produk R-02 bersama EDC R-01, lalu memisahkan gas, air asam, dan EDC basah
A6: Unjuk Kerja | B6: =3/1000000 -> 3e-06 | C6: Kadar FeCl₃ dalam EDC setelah kontak dengan air asam (fraksi berat)
B7: =2.4/1000 -> 0.0024 | C7: EDC terbawa gas vent (kg/kg EDC R-01 + R-02)
B8: 0.002 | C8: Kadar air dalam fase EDC keluar dekanter (fraksi berat)
B9: 0.0008 | C9: Kadar EDC dalam fase air asam (fraksi berat)
B10: 0.75 | C10: Efisiensi pompa P-101
A12: Basis Perhitungan | B12: ='NME-1 Klorinasi Langsung'!$B$16 -> 6100.5722 | C12: kg/h aliran etilena ke R-01 (NME-1)
A14: Substance | B14: Inlet | J14: Outlet
B15: Aliran 15 | F15: Aliran 18 | J15: Aliran 25 | N15: Aliran 28 | R15: Aliran 29
B16: ẋᵢ | C16: ṁᵢ (kg/h) | D16: ẏᵢ | E16: ṅᵢ (kmol/h) | F16: ẋᵢ | G16: ṁᵢ (kg/h) | H16: ẏᵢ | I16: ṅᵢ (kmol/h) | J16: ẋᵢ | K16: ṁᵢ (kg/h) | L16: ẏᵢ | M16: ṅᵢ (kmol/h) | N16: ẋᵢ | O16: ṁᵢ (kg/h) | P16: ẏᵢ | Q16: ṅᵢ (kmol/h) | R16: ẋᵢ | S16: ṁᵢ (kg/h) | T16: ẏᵢ | U16: ṅᵢ (kmol/h)
A17: C₂H₄ | B17: =C17/C$38 -> 0 | C17: =E17*'Data Komponen'!$D$3 -> 0 | D17: =E17/E$38 -> 0 | E17: ='NME-1 Klorinasi Langsung'!Q21 -> 0 | F17: =G17/G$38 -> 0.00066170751 | G17: =I17*'Data Komponen'!$D$3 -> 28.508389 | H17: =I17/I$38 -> 0.00093556297 | I17: ='NME-2 Oksiklorinasi'!Q20 -> 1.0161969 | J17: =K17/K$38 -> 0.0014629385 | K17: =M17*'Data Komponen'!$D$3 -> 28.508389 | L17: =M17/M$38 -> 0.0014973251 | M17: =E17+I17 -> 1.0161969 | N17: =O17/O$38 -> 0 | O17: =Q17*'Data Komponen'!$D$3 -> 0 | P17: =Q17/Q$38 -> 0 | Q17: =0 -> 0 | R17: =S17/S$38 -> 0 | S17: =U17*'Data Komponen'!$D$3 -> 0 | T17: =U17/U$38 -> 0 | U17: =0 -> 0
A18: CH₄ | B18: =C18/C$38 -> 0 | C18: =E18*'Data Komponen'!$D$4 -> 0 | D18: =E18/E$38 -> 0 | E18: ='NME-1 Klorinasi Langsung'!Q22 -> 0 | F18: =G18/G$38 -> 3.0642114e-05 | G18: =I18*'Data Komponen'!$D$4 -> 1.3201562 | H18: =I18/I$38 -> 7.5759115e-05 | I18: ='NME-2 Oksiklorinasi'!Q21 -> 0.082288614 | J18: =K18/K$38 -> 6.7745232e-05 | K18: =M18*'Data Komponen'!$D$4 -> 1.3201562 | L18: =M18/M$38 -> 0.00012124895 | M18: =E18+I18 -> 0.082288614 | N18: =O18/O$38 -> 0 | O18: =Q18*'Data Komponen'!$D$4 -> 0 | P18: =Q18/Q$38 -> 0 | Q18: =0 -> 0 | R18: =S18/S$38 -> 0 | S18: =U18*'Data Komponen'!$D$4 -> 0 | T18: =U18/U$38 -> 0 | U18: =0 -> 0
A19: C₂H₆ | B19: =C19/C$38 -> 0 | C19: =E19*'Data Komponen'!$D$5 -> 0 | D19: =E19/E$38 -> 0 | E19: ='NME-1 Klorinasi Langsung'!Q23 -> 0 | F19: =G19/G$38 -> 1.6721734e-06 | G19: =I19*'Data Komponen'!$D$5 -> 0.072042359 | H19: =I19/I$38 -> 2.2057163e-06 | I19: ='NME-2 Oksiklorinasi'!Q22 -> 0.0023958217 | J19: =K19/K$38 -> 3.6969309e-06 | K19: =M19*'Data Komponen'!$D$5 -> 0.072042359 | L19: =M19/M$38 -> 3.5301465e-06 | M19: =E19+I19 -> 0.0023958217 | N19: =O19/O$38 -> 0 | O19: =Q19*'Data Komponen'!$D$5 -> 0 | P19: =Q19/Q$38 -> 0 | Q19: =0 -> 0 | R19: =S19/S$38 -> 0 | S19: =U19*'Data Komponen'!$D$5 -> 0 | T19: =U19/U$38 -> 0 | U19: =0 -> 0
A20: C₂H₂ | B20: =C20/C$38 -> 0 | C20: =E20*'Data Komponen'!$D$6 -> 0 | D20: =E20/E$38 -> 0 | E20: ='NME-1 Klorinasi Langsung'!Q24 -> 0 | F20: =G20/G$38 -> 6.4045279e-07 | G20: =I20*'Data Komponen'!$D$6 -> 0.02759267 | H20: =I20/I$38 -> 9.7562125e-07 | I20: ='NME-2 Oksiklorinasi'!Q23 -> 0.0010597077 | J20: =K20/K$38 -> 1.4159474e-06 | K20: =M20*'Data Komponen'!$D$6 -> 0.02759267 | L20: =M20/M$38 -> 1.5614365e-06 | M20: =E20+I20 -> 0.0010597077 | N20: =O20/O$38 -> 0 | O20: =Q20*'Data Komponen'!$D$6 -> 0 | P20: =Q20/Q$38 -> 0 | Q20: =0 -> 0 | R20: =S20/S$38 -> 0 | S20: =U20*'Data Komponen'!$D$6 -> 0 | T20: =U20/U$38 -> 0 | U20: =0 -> 0
A21: Cl₂ | B21: =C21/C$38 -> 0 | C21: =E21*'Data Komponen'!$D$7 -> 0 | D21: =E21/E$38 -> 0 | E21: ='NME-1 Klorinasi Langsung'!Q25 -> 0 | F21: =G21/G$38 -> 0.0050937019 | G21: =I21*'Data Komponen'!$D$7 -> 219.4523 | H21: =I21/I$38 -> 0.0028494328 | I21: ='NME-2 Oksiklorinasi'!Q24 -> 3.0950187 | J21: =K21/K$38 -> 0.01126143 | K21: =M21*'Data Komponen'!$D$7 -> 219.4523 | L21: =M21/M$38 -> 0.004560385 | M21: =E21+I21 -> 3.0950187 | N21: =O21/O$38 -> 0 | O21: =Q21*'Data Komponen'!$D$7 -> 0 | P21: =Q21/Q$38 -> 0 | Q21: =0 -> 0 | R21: =S21/S$38 -> 0 | S21: =U21*'Data Komponen'!$D$7 -> 0 | T21: =U21/U$38 -> 0 | U21: =0 -> 0
A22: CₙHₘ | B22: =C22/C$38 -> 0 | C22: =E22*'Data Komponen'!$D$8 -> 0 | D22: =E22/E$38 -> 0 | E22: ='NME-1 Klorinasi Langsung'!Q26 -> 0 | F22: =G22/G$38 -> 0 | G22: =I22*'Data Komponen'!$D$8 -> 0 | H22: =I22/I$38 -> 0 | I22: ='NME-2 Oksiklorinasi'!Q25 -> 0 | J22: =K22/K$38 -> 0 | K22: =M22*'Data Komponen'!$D$8 -> 0 | L22: =M22/M$38 -> 0 | M22: =E22+I22 -> 0 | N22: =O22/O$38 -> 0 | O22: =Q22*'Data Komponen'!$D$8 -> 0 | P22: =Q22/Q$38 -> 0 | Q22: =0 -> 0 | R22: =S22/S$38 -> 0 | S22: =U22*'Data Komponen'!$D$8 -> 0 | T22: =U22/U$38 -> 0 | U22: =0 -> 0
A23: H₂O | B23: =C23/C$38 -> 8.6289026e-06 | C23: =E23*'Data Komponen'!$D$9 -> 0.18452558 | D23: =E23/E$38 -> 4.7406553e-05 | E23: ='NME-1 Klorinasi Langsung'!Q27 -> 0.010242886 | F23: =G23/G$38 -> 0.084303811 | G23: =I23*'Data Komponen'!$D$9 -> 3632.0667 | H23: =I23/I$38 -> 0.18561569 | I23: ='NME-2 Oksiklorinasi'!Q26 -> 201.61347 | J23: =K23/K$38 -> 0 | K23: =M23*'Data Komponen'!$D$9 -> 0 | L23: =M23/M$38 -> 0 | M23: =0 -> 0 | N23: =O23/O$38 -> 0.94297682 | O23: =Q23*'Data Komponen'!$D$9 -> 3549.819 | P23: =Q23/Q$38 -> 0.971662 | Q23: =E23+I23-U23 -> 197.04796 | R23: =S23/S$38 -> 0.002 | S23: =U23*'Data Komponen'!$D$9 -> 82.432214 | T23: =U23/U$38 -> 0.010874386 | U23: =$B$8/(1-$B$8)*(S31+S32+S25+S26+S35+S37+S34)/'Data Komponen'!$D$9 -> 4.5757543
A24: CₓHᵧCl | B24: =C24/C$38 -> 0 | C24: =E24*'Data Komponen'!$D$10 -> 0 | D24: =E24/E$38 -> 0 | E24: ='NME-1 Klorinasi Langsung'!Q28 -> 0 | F24: =G24/G$38 -> 0 | G24: =I24*'Data Komponen'!$D$10 -> 0 | H24: =I24/I$38 -> 0 | I24: ='NME-2 Oksiklorinasi'!Q27 -> 0 | J24: =K24/K$38 -> 0 | K24: =M24*'Data Komponen'!$D$10 -> 0 | L24: =M24/M$38 -> 0 | M24: =E24+I24 -> 0 | N24: =O24/O$38 -> 0 | O24: =Q24*'Data Komponen'!$D$10 -> 0 | P24: =Q24/Q$38 -> 0 | Q24: =0 -> 0 | R24: =S24/S$38 -> 0 | S24: =U24*'Data Komponen'!$D$10 -> 0 | T24: =U24/U$38 -> 0 | U24: =0 -> 0
A25: Br₂ | B25: =C25/C$38 -> 6.4716769e-05 | C25: =E25*'Data Komponen'!$D$11 -> 1.3839419 | D25: =E25/E$38 -> 4.0080709e-05 | E25: ='NME-1 Klorinasi Langsung'!Q29 -> 0.0086600287 | F25: =G25/G$38 -> 0 | G25: =I25*'Data Komponen'!$D$11 -> 0 | H25: =I25/I$38 -> 0 | I25: ='NME-2 Oksiklorinasi'!Q28 -> 0 | J25: =K25/K$38 -> 0 | K25: =M25*'Data Komponen'!$D$11 -> 0 | L25: =M25/M$38 -> 0 | M25: =0 -> 0 | N25: =O25/O$38 -> 0 | O25: =Q25*'Data Komponen'!$D$11 -> 0 | P25: =Q25/Q$38 -> 0 | Q25: =0 -> 0 | R25: =S25/S$38 -> 3.3577695e-05 | S25: =U25*'Data Komponen'!$D$11 -> 1.3839419 | T25: =U25/U$38 -> 2.0580759e-05 | U25: =E25+I25 -> 0.0086600287
A26: NCl₃ | B26: =C26/C$38 -> 3.5953761e-06 | C26: =E26*'Data Komponen'!$D$12 -> 0.076885659 | D26: =E26/E$38 -> 2.9563863e-06 | E26: ='NME-1 Klorinasi Langsung'!Q30 -> 0.0006387709 | F26: =G26/G$38 -> 0 | G26: =I26*'Data Komponen'!$D$12 -> 0 | H26: =I26/I$38 -> 0 | I26: ='NME-2 Oksiklorinasi'!Q29 -> 0 | J26: =K26/K$38 -> 0 | K26: =M26*'Data Komponen'!$D$12 -> 0 | L26: =M26/M$38 -> 0 | M26: =0 -> 0 | N26: =O26/O$38 -> 0 | O26: =Q26*'Data Komponen'!$D$12 -> 0 | P26: =Q26/Q$38 -> 0 | Q26: =0 -> 0 | R26: =S26/S$38 -> 1.8654275e-06 | S26: =U26*'Data Komponen'!$D$12 -> 0.076885659 | T26: =U26/U$38 -> 1.5180539e-06 | U26: =E26+I26 -> 0.0006387709
A27: H₂ | B27: =C27/C$38 -> 0 | C27: =E27*'Data Komponen'!$D$13 -> 0 | D27: =E27/E$38 -> 0 | E27: ='NME-1 Klorinasi Langsung'!Q31 -> 0 | F27: =G27/G$38 -> 0 | G27: =I27*'Data Komponen'!$D$13 -> 0 | H27: =I27/I$38 -> 0 | I27: ='NME-2 Oksiklorinasi'!Q30 -> 0 | J27: =K27/K$38 -> 0 | K27: =M27*'Data Komponen'!$D$13 -> 0 | L27: =M27/M$38 -> 0 | M27: =E27+I27 -> 0 | N27: =O27/O$38 -> 0 | O27: =Q27*'Data Komponen'!$D$13 -> 0 | P27: =Q27/Q$38 -> 0 | Q27: =0 -> 0 | R27: =S27/S$38 -> 0 | S27: =U27*'Data Komponen'!$D$13 -> 0 | T27: =U27/U$38 -> 0 | U27: =0 -> 0
A28: O₂ | B28: =C28/C$38 -> 0 | C28: =E28*'Data Komponen'!$D$14 -> 0 | D28: =E28/E$38 -> 0 | E28: ='NME-1 Klorinasi Langsung'!Q32 -> 0 | F28: =G28/G$38 -> 0.044379766 | G28: =I28*'Data Komponen'!$D$14 -> 1912.0164 | H28: =I28/I$38 -> 0.055011103 | I28: ='NME-2 Oksiklorinasi'!Q31 -> 59.75238 | J28: =K28/K$38 -> 0.098117171 | K28: =M28*'Data Komponen'!$D$14 -> 1912.0164 | L28: =M28/M$38 -> 0.088042717 | M28: =E28+I28 -> 59.75238 | N28: =O28/O$38 -> 0 | O28: =Q28*'Data Komponen'!$D$14 -> 0 | P28: =Q28/Q$38 -> 0 | Q28: =0 -> 0 | R28: =S28/S$38 -> 0 | S28: =U28*'Data Komponen'!$D$14 -> 0 | T28: =U28/U$38 -> 0 | U28: =0 -> 0
A29: N₂ | B29: =C29/C$38 -> 0 | C29: =E29*'Data Komponen'!$D$15 -> 0 | D29: =E29/E$38 -> 0 | E29: ='NME-1 Klorinasi Langsung'!Q33 -> 0 | F29: =G29/G$38 -> 0.39771702 | G29: =I29*'Data Komponen'!$D$15 -> 17134.869 | H29: =I29/I$38 -> 0.56311981 | I29: ='NME-2 Oksiklorinasi'!Q32 -> 611.65377 | J29: =K29/K$38 -> 0.87929416 | K29: =M29*'Data Komponen'!$D$15 -> 17134.869 | L29: =M29/M$38 -> 0.90124712 | M29: =E29+I29 -> 611.65377 | N29: =O29/O$38 -> 0 | O29: =Q29*'Data Komponen'!$D$15 -> 0 | P29: =Q29/Q$38 -> 0 | Q29: =0 -> 0 | R29: =S29/S$38 -> 0 | S29: =U29*'Data Komponen'!$D$15 -> 0 | T29: =U29/U$38 -> 0 | U29: =0 -> 0
A30: CO₂ | B30: =C30/C$38 -> 0 | C30: =E30*'Data Komponen'!$D$16 -> 0 | D30: =E30/E$38 -> 0 | E30: ='NME-1 Klorinasi Langsung'!Q34 -> 0 | F30: =G30/G$38 -> 0.0020761209 | G30: =I30*'Data Komponen'!$D$16 -> 89.445654 | H30: =I30/I$38 -> 0.0018711259 | I30: ='NME-2 Oksiklorinasi'!Q33 -> 2.0323939 | J30: =K30/K$38 -> 0.0045899996 | K30: =M30*'Data Komponen'!$D$16 -> 89.445654 | L30: =M30/M$38 -> 0.0029946502 | M30: =E30+I30 -> 2.0323939 | N30: =O30/O$38 -> 0 | O30: =Q30*'Data Komponen'!$D$16 -> 0 | P30: =Q30/Q$38 -> 0 | Q30: =0 -> 0 | R30: =S30/S$38 -> 0 | S30: =U30*'Data Komponen'!$D$16 -> 0 | T30: =U30/U$38 -> 0 | U30: =0 -> 0
A31: EDC | B31: =C31/C$38 -> 0.9994221 | C31: =E31*'Data Komponen'!$D$17 -> 21372.236 | D31: =E31/E$38 -> 0.99956429 | E31: ='NME-1 Klorinasi Langsung'!Q35 -> 215.97062 | F31: =G31/G$38 -> 0.45842475 | G31: =I31*'Data Komponen'!$D$17 -> 19750.344 | H31: =I31/I$38 -> 0.18374457 | I31: ='NME-2 Oksiklorinasi'!Q34 -> 199.58108 | J31: =K31/K$38 -> 0.005070074 | K31: =M31*'Data Komponen'!$D$17 -> 98.800897 | L31: =M31/M$38 -> 0.0014711055 | M31: =$B$7*('NME-1 Klorinasi Langsung'!Q35+'NME-1 Klorinasi Langsung'!U35+'NME-2 Oksiklorinasi'!Q34) -> 0.99840234 | N31: =O31/O$38 -> 0.0008 | O31: =Q31*'Data Komponen'!$D$17 -> 3.0115854 | P31: =Q31/Q$38 -> 0.00015006629 | Q31: =$B$9/(1-$B$9)*(O33+O23+O34)/'Data Komponen'!$D$17 -> 0.030432658 | R31: =S31/S$38 -> 0.99526061 | S31: =U31*'Data Komponen'!$D$17 -> 41020.768 | T31: =U31/U$38 -> 0.98512319 | U31: =E31+I31-M31-Q31 -> 414.52286
A32: TCE | B32: =C32/C$38 -> 0.00030054052 | C32: =E32*'Data Komponen'!$D$18 -> 6.4269371 | D32: =E32/E$38 -> 0.00022297415 | E32: ='NME-1 Klorinasi Langsung'!Q36 -> 0.048176856 | F32: =G32/G$38 -> 0 | G32: =I32*'Data Komponen'!$D$18 -> 0 | H32: =I32/I$38 -> 0 | I32: ='NME-2 Oksiklorinasi'!Q35 -> 0 | J32: =K32/K$38 -> 0 | K32: =M32*'Data Komponen'!$D$18 -> 0 | L32: =M32/M$38 -> 0 | M32: =0 -> 0 | N32: =O32/O$38 -> 0 | O32: =Q32*'Data Komponen'!$D$18 -> 0 | P32: =Q32/Q$38 -> 0 | Q32: =0 -> 0 | R32: =S32/S$38 -> 0.00015593266 | S32: =U32*'Data Komponen'!$D$18 -> 6.4269371 | T32: =U32/U$38 -> 0.00011449342 | U32: =E32+I32 -> 0.048176856
A33: HCl | B33: =C33/C$38 -> 0 | C33: =E33*'Data Komponen'!$D$19 -> 0 | D33: =E33/E$38 -> 0 | E33: ='NME-1 Klorinasi Langsung'!Q37 -> 0 | F33: =G33/G$38 -> 0.0048160155 | G33: =I33*'Data Komponen'!$D$19 -> 207.48872 | H33: =I33/I$38 -> 0.0052391526 | I33: ='NME-2 Oksiklorinasi'!Q36 -> 5.6907028 | J33: =K33/K$38 -> 0 | K33: =M33*'Data Komponen'!$D$19 -> 0 | L33: =M33/M$38 -> 0 | M33: =0 -> 0 | N33: =O33/O$38 -> 0.055117472 | O33: =Q33*'Data Komponen'!$D$19 -> 207.48872 | P33: =Q33/Q$38 -> 0.02806139 | Q33: =E33+I33 -> 5.6907028 | R33: =S33/S$38 -> 0 | S33: =U33*'Data Komponen'!$D$19 -> 0 | T33: =U33/U$38 -> 0 | U33: =0 -> 0
A34: FeCl₃ | B34: =C34/C$38 -> 0.00020041582 | C34: =E34*'Data Komponen'!$D$20 -> 4.285811 | D34: =E34/E$38 -> 0.00012228903 | E34: ='NME-1 Klorinasi Langsung'!Q38 -> 0.026422351 | F34: =G34/G$38 -> 0 | G34: =I34*'Data Komponen'!$D$20 -> 0 | H34: =I34/I$38 -> 0 | I34: ='NME-2 Oksiklorinasi'!Q37 -> 0 | J34: =K34/K$38 -> 0 | K34: =M34*'Data Komponen'!$D$20 -> 0 | L34: =M34/M$38 -> 0 | M34: =0 -> 0 | N34: =O34/O$38 -> 0.001105706 | O34: =Q34*'Data Komponen'!$D$20 -> 4.1624099 | P34: =Q34/Q$38 -> 0.00012653963 | Q34: =E34+I34-U34 -> 0.025661574 | R34: =S34/S$38 -> 2.994e-06 | S34: =U34*'Data Komponen'!$D$20 -> 0.12340102 | T34: =U34/U$38 -> 1.8080035e-06 | U34: =$B$6/(1-$B$6)*(S31+S32+S25+S26+S35+S37)/'Data Komponen'!$D$20 -> 0.0007607767
A35: C₂H₅Cl | B35: =C35/C$38 -> 0 | C35: =E35*'Data Komponen'!$D$21 -> 0 | D35: =E35/E$38 -> 0 | E35: ='NME-1 Klorinasi Langsung'!Q39 -> 0 | F35: =G35/G$38 -> 0.0024347364 | G35: =I35*'Data Komponen'!$D$21 -> 104.89591 | H35: =I35/I$38 -> 0.0014969008 | I35: ='NME-2 Oksiklorinasi'!Q38 -> 1.6259151 | J35: =K35/K$38 -> 0 | K35: =M35*'Data Komponen'!$D$21 -> 0 | L35: =M35/M$38 -> 0 | M35: =0 -> 0 | N35: =O35/O$38 -> 0 | O35: =Q35*'Data Komponen'!$D$21 -> 0 | P35: =Q35/Q$38 -> 0 | Q35: =0 -> 0 | R35: =S35/S$38 -> 0.0025450223 | S35: =U35*'Data Komponen'!$D$21 -> 104.89591 | T35: =U35/U$38 -> 0.0038640249 | U35: =E35+I35 -> 1.6259151
A36: VCM | B36: =C36/C$38 -> 0 | C36: =E36*'Data Komponen'!$D$22 -> 0 | D36: =E36/E$38 -> 0 | E36: ='NME-1 Klorinasi Langsung'!Q40 -> 0 | F36: =G36/G$38 -> 5.9420336e-05 | G36: =I36*'Data Komponen'!$D$22 -> 2.5600103 | H36: =I36/I$38 -> 3.7711233e-05 | I36: ='NME-2 Oksiklorinasi'!Q39 -> 0.040961475 | J36: =K36/K$38 -> 0.00013136967 | K36: =M36*'Data Komponen'!$D$22 -> 2.5600103 | L36: =M36/M$38 -> 6.0355079e-05 | M36: =E36+I36 -> 0.040961475 | N36: =O36/O$38 -> 0 | O36: =Q36*'Data Komponen'!$D$22 -> 0 | P36: =Q36/Q$38 -> 0 | Q36: =0 -> 0 | R36: =S36/S$38 -> 0 | S36: =U36*'Data Komponen'!$D$22 -> 0 | T36: =U36/U$38 -> 0 | U36: =0 -> 0
A37: C₄H₈Cl₂ (berat) | B37: =C37/C$38 -> 0 | C37: =E37*'Data Komponen'!$D$23 -> 0 | D37: =E37/E$38 -> 0 | E37: ='NME-1 Klorinasi Langsung'!Q41 -> 0 | F37: =G37/G$38 -> 0 | G37: =I37*'Data Komponen'!$D$23 -> 0 | H37: =I37/I$38 -> 0 | I37: ='NME-2 Oksiklorinasi'!Q40 -> 0 | J37: =K37/K$38 -> 0 | K37: =M37*'Data Komponen'!$D$23 -> 0 | L37: =M37/M$38 -> 0 | M37: =0 -> 0 | N37: =O37/O$38 -> 0 | O37: =Q37*'Data Komponen'!$D$23 -> 0 | P37: =Q37/Q$38 -> 0 | Q37: =0 -> 0 | R37: =S37/S$38 -> 0 | S37: =U37*'Data Komponen'!$D$23 -> 0 | T37: =U37/U$38 -> 0 | U37: =E37+I37 -> 0
A38: Sub Total | B38: =SUM(B17:B37) -> 1 | C38: =SUM(C17:C37) -> 21384.594 | D38: =SUM(D17:D37) -> 1 | E38: =SUM(E17:E37) -> 216.06476 | F38: =SUM(F17:F37) -> 1 | G38: =SUM(G17:G37) -> 43083.066 | H38: =SUM(H17:H37) -> 1 | I38: =SUM(I17:I37) -> 1086.1876 | ... U38: =SUM(U17:U37) -> 420.78277
A39: TOTAL MASSA | B39: =C38+G38 -> 64467.661 | J39: =K38+O38+S38 -> 64467.661
A40: Selisih (Inlet − Outlet), kg/h | B40: =B39-J39 -> -1.7462298e-10
A43: Neraca Energi P-101: Pompa EDC dari R-01
A44: Reference state: unsur pada 25 °C dan 1 atm (metode panas pembentukan)
A45: No. aliran PFD | B45: 14 | D45: 15
A46: Dari | B46: R-01 | D46: P-101
...

Sheet NME-4 Kolom Ringan
A3: Neraca Massa dan Energi
A4: NM Blok 4: Pemisahan Fraksi Ringan (Kolom Ringan)
A5: Tujuan: | B5: Memisahkan air dan komponen yang lebih ringan dari EDC
A6: Unjuk Kerja | B6: =35/1000000 -> 3.5e-05 | C6: Kadar air dalam EDC kering di produk bawah (fraksi berat)
B7: =10/1000000 -> 1e-05 | C7: Kadar VCM dalam produk bawah (fraksi berat)
B8: =3/1000 -> 0.003 | C8: EDC terbawa keluar lewat vent kolom (kg/kg EDC R-01 + R-02)
B9: Ringan | C9: Etil klorida, Br₂, NCl₃, dan gas terlarut ke distilat
B10: 0.6 | C10: Boil-up ratio V/B reboiler KD-101
A12: Basis Perhitungan | B12: ='NME-1 Klorinasi Langsung'!$B$16 -> 6100.5722 | C12: kg/h aliran etilena ke R-01 (NME-1)
A14: Substance | B14: Inlet | J14: Outlet
