Workbook

Sheet Data
A1: Tabel 10-6. Data dari Reaktor Diferensial (Hidrodemetilasi Toluena)
A3: Set | B3: Run | C3: r'T × 10^10 (g mol toluena / g kat·s) | D3: Toluena, PT (atm) | E3: Hidrogen, PH2 (atm) | F3: Metana, PM (atm) | G3: Benzena, PB (atm)
A4: A | B4: 1 | C4: 71 | D4: 1 | E4: 1 | F4: 1 | G4: 0
A5: A | B5: 2 | C5: 71.3 | D5: 1 | E5: 1 | F5: 4 | G5: 0
A6: B | B6: 3 | C6: 41.6 | D6: 1 | E6: 1 | F6: 0 | G6: 1
A7: B | B7: 4 | C7: 19.7 | D7: 1 | E7: 1 | F7: 0 | G7: 4
A8: B | B8: 5 | C8: 42 | D8: 1 | E8: 1 | F8: 1 | G8: 1
A9: B | B9: 6 | C9: 17.1 | D9: 1 | E9: 1 | F9: 0 | G9: 5
A10: C | B10: 7 | C10: 71.8 | D10: 1 | E10: 1 | F10: 0 | G10: 0
A11: C | B11: 8 | C11: 142 | D11: 1 | E11: 2 | F11: 0 | G11: 0
A12: C | B12: 9 | C12: 284 | D12: 1 | E12: 4 | F12: 0 | G12: 0
A13: D | B13: 10 | C13: 47 | D13: 0.5 | E13: 1 | F13: 0 | G13: 0
A14: D | B14: 11 | C14: 71.3 | D14: 1 | E14: 1 | F14: 0 | G14: 0
A15: D | B15: 12 | C15: 117 | D15: 5 | E15: 1 | F15: 0 | G15: 0
... A19: D | B19: 16 | C19: 41.8 | D19: 1 | E19: 1 | F19: 1 | G19: 1
A21: Catatan: PH ≡ PH2. Semua nilai diketik ulang dari gambar Tabel 10-6 yang diberikan pengguna (teks biru = data input).
A22: Run 16 (Set D) memiliki PM = 1 dan PB = 1, sehingga tidak diikutkan dalam grafik r'T vs PT.

Sheet Grafik
A1: Grafik Laju Reaksi r'T × 10^10 terhadap Tekanan Parsial
A2: Tabel bantu di kolom A–C mengambil nilai dari sheet Data (teks hijau = link antar-sheet).
A4: Set A — pengaruh metana
A5: Run | B5: PM (atm) | C5: r'T × 10^10
A6: =Data!B4 -> 1 | B6: =Data!F4 -> 1 | C6: =Data!C4 -> 71
A7: =Data!B5 -> 2 | B7: =Data!F5 -> 4 | C7: =Data!C5 -> 71.3
A20: Set B — pengaruh benzena (PM = 0)
A21: Run | B21: PB (atm) | C21: r'T × 10^10
A22: =Data!B6 -> 3 | B22: =Data!G6 -> 1 | C22: =Data!C6 -> 41.6
A23: =Data!B7 -> 4 | B23: =Data!G7 -> 4 | C23: =Data!C7 -> 19.7
A24: =Data!B9 -> 6 | B24: =Data!G9 -> 5 | C24: =Data!C9 -> 17.1
A26: Set B — PM = 1
A27: Run | B27: PB (atm) | C27: r'T × 10^10
A28: =Data!B8 -> 5 | B28: =Data!G8 -> 1 | C28: =Data!C8 -> 42
A40: Set C — pengaruh hidrogen
A41: Run | B41: PH2 (atm) | C41: r'T × 10^10
A42: =Data!B10 -> 7 | B42: =Data!E10 -> 1 | C42: =Data!C10 -> 71.8
A43: =Data!B11 -> 8 | B43: =Data!E11 -> 2 | C43: =Data!C11 -> 142
A44: =Data!B12 -> 9 | B44: =Data!E12 -> 4 | C44: =Data!C12 -> 284
A56: Set D — pengaruh toluena
A57: Run | B57: PT (atm) | C57: r'T × 10^10
A58: =Data!B13 -> 10 | B58: =Data!D13 -> 0.5 | C58: =Data!C13 -> 47
A59: =Data!B14 -> 11 | B59: =Data!D14 -> 1 | C59: =Data!C14 -> 71.3
A60: =Data!B15 -> 12 | B60: =Data!D15 -> 5 | C60: =Data!C15 -> 117
A61: =Data!B16 -> 13 | B61: =Data!D16 -> 10 | C61: =Data!C16 -> 127
A62: =Data!B17 -> 14 | B62: =Data!D17 -> 15 | C62: =Data!C17 -> 131
A63: =Data!B18 -> 15 | B63: =Data!D18 -> 20 | C63: =Data!C18 -> 133

Sheet Perhitungan
A1: Perhitungan Regresi Linear Berganda
A2: Model: -r'T = k·PH2·PT / (1 + KB·PB + KT·PT) → y = PH2·PT/(-r'T) = 1/k + (KB/k)·PB + (KT/k)·PT = a0 + a1·x1 + a2·x2
A3: -r'T dipakai sesuai tabel (nilai × 10^10). Metana tidak dimasukkan ke model karena Set A menunjukkan PM tidak berpengaruh. Teks hijau = link ke sheet Data.
A5: Run | B5: PH2 (atm) | C5: PT (atm) | D5: -r'T × 10^10 | E5: y = PH2·PT/(-rT) | F5: x1 = PB | G5: x2 = PT | H5: x1·y | I5: x2·y | J5: x1·x2 | K5: x1² | L5: x2² | M5: ŷ = a0 + a1·x1 + a2·x2 | N5: Residual y − ŷ
A6: =Data!B4 -> 1 | B6: =Data!E4 -> 1 | C6: =Data!D4 -> 1 | D6: =Data!C4 -> 71 | E6: =B6*C6/D6 -> 0.014084507 | F6: =Data!G4 -> 0 | G6: =C6 -> 1 | H6: =F6*E6 -> 0 | I6: =G6*E6 -> 0.014084507 | J6: =F6*G6 -> 0 | K6: =F6^2 -> 0 | L6: =G6^2 -> 1 | M6: =$C$38+$C$39*F6+$C$40*G6 -> 0.014279515 | N6: =E6-M6 -> -0.00019500804
A7: =Data!B5 -> 2 | B7: =Data!E5 -> 1 | C7: =Data!D5 -> 1 | D7: =Data!C5 -> 71.3 | E7: =B7*C7/D7 -> 0.014025245 | F7: =Data!G5 -> 0 | G7: =C7 -> 1 | H7: =F7*E7 -> 0 | I7: =G7*E7 -> 0.014025245 | J7: =F7*G7 -> 0 | K7: =F7^2 -> 0 | L7: =G7^2 -> 1 | M7: =$C$38+$C$39*F7+$C$40*G7 -> 0.014279515 | N7: =E7-M7 -> -0.00025426964
A8: =Data!B6 -> 3 | B8: =Data!E6 -> 1 | C8: =Data!D6 -> 1 | D8: =Data!C6 -> 41.6 | E8: =B8*C8/D8 -> 0.024038462 | F8: =Data!G6 -> 1 | G8: =C8 -> 1 | H8: =F8*E8 -> 0.024038462 | I8: =G8*E8 -> 0.024038462 | J8: =F8*G8 -> 1 | K8: =F8^2 -> 1 | L8: =G8^2 -> 1 | M8: =$C$38+$C$39*F8+$C$40*G8 -> 0.023276347 | N8: =E8-M8 -> 0.00076211474
A9: =Data!B7 -> 4 | B9: =Data!E7 -> 1 | C9: =Data!D7 -> 1 | D9: =Data!C7 -> 19.7 | E9: =B9*C9/D9 -> 0.050761421 | F9: =Data!G7 -> 4 | G9: =C9 -> 1 | H9: =F9*E9 -> 0.20304569 | I9: =G9*E9 -> 0.050761421 | J9: =F9*G9 -> 4 | K9: =F9^2 -> 16 | L9: =G9^2 -> 1 | M9: =$C$38+$C$39*F9+$C$40*G9 -> 0.050266842 | N9: =E9-M9 -> 0.00049457938
A10: =Data!B8 -> 5 | B10: =Data!E8 -> 1 | C10: =Data!D8 -> 1 | D10: =Data!C8 -> 42 | E10: =B10*C10/D10 -> 0.023809524 | F10: =Data!G8 -> 1 | G10: =C10 -> 1 | H10: =F10*E10 -> 0.023809524 | I10: =G10*E10 -> 0.023809524 | J10: =F10*G10 -> 1 | K10: =F10^2 -> 1 | L10: =G10^2 -> 1 | M10: =$C$38+$C$39*F10+$C$40*G10 -> 0.023276347 | N10: =E10-M10 -> 0.00053317701
A11: =Data!B9 -> 6 | B11: =Data!E9 -> 1 | C11: =Data!D9 -> 1 | D11: =Data!C9 -> 17.1 | E11: =B11*C11/D11 -> 0.058479532 | F11: =Data!G9 -> 5 | G11: =C11 -> 1 | H11: =F11*E11 -> 0.29239766 | I11: =G11*E11 -> 0.058479532 | J11: =F11*G11 -> 5 | K11: =F11^2 -> 25 | L11: =G11^2 -> 1 | M11: =$C$38+$C$39*F11+$C$40*G11 -> 0.059263674 | N11: =E11-M11 -> -0.00078414149
A12: =Data!B10 -> 7 | B12: =Data!E10 -> 1 | C12: =Data!D10 -> 1 | D12: =Data!C10 -> 71.8 | E12: =B12*C12/D12 -> 0.013927577 | F12: =Data!G10 -> 0 | G12: =C12 -> 1 | H12: =F12*E12 -> 0 | I12: =G12*E12 -> 0.013927577 | J12: =F12*G12 -> 0 | K12: =F12^2 -> 0 | L12: =G12^2 -> 1 | M12: =$C$38+$C$39*F12+$C$40*G12 -> 0.014279515 | N12: =E12-M12 -> -0.00035193848
A13: =Data!B11 -> 8 | B13: =Data!E11 -> 2 | C13: =Data!D11 -> 1 | D13: =Data!C11 -> 142 | E13: =B13*C13/D13 -> 0.014084507 | F13: =Data!G11 -> 0 | G13: =C13 -> 1 | H13: =F13*E13 -> 0 | I13: =G13*E13 -> 0.014084507 | J13: =F13*G13 -> 0 | K13: =F13^2 -> 0 | L13: =G13^2 -> 1 | M13: =$C$38+$C$39*F13+$C$40*G13 -> 0.014279515 | N13: =E13-M13 -> -0.00019500804
A14: =Data!B12 -> 9 | B14: =Data!E12 -> 4 | C14: =Data!D12 -> 1 | D14: =Data!C12 -> 284 | E14: =B14*C14/D14 -> 0.014084507 | F14: =Data!G12 -> 0 | G14: =C14 -> 1 | H14: =F14*E14 -> 0 | I14: =G14*E14 -> 0.014084507 | J14: =F14*G14 -> 0 | K14: =F14^2 -> 0 | L14: =G14^2 -> 1 | M14: =$C$38+$C$39*F14+$C$40*G14 -> 0.014279515 | N14: =E14-M14 -> -0.00019500804
A15: =Data!B13 -> 10 | B15: =Data!E13 -> 1 | C15: =Data!D13 -> 0.5 | D15: =Data!C13 -> 47 | E15: =B15*C15/D15 -> 0.010638298 | F15: =Data!G13 -> 0 | G15: =C15 -> 0.5 | H15: =F15*E15 -> 0 | I15: =G15*E15 -> 0.0053191489 | J15: =F15*G15 -> 0 | K15: =F15^2 -> 0 | L15: =G15^2 -> 0.25 | M15: =$C$38+$C$39*F15+$C$40*G15 -> 0.010699262 | N15: =E15-M15 -> -6.0964406e-05
A16: =Data!B14 -> 11 | B16: =Data!E14 -> 1 | C16: =Data!D14 -> 1 | D16: =Data!C14 -> 71.3 | E16: =B16*C16/D16 -> 0.014025245 | F16: =Data!G14 -> 0 | G16: =C16 -> 1 | H16: =F16*E16 -> 0 | I16: =G16*E16 -> 0.014025245 | J16: =F16*G16 -> 0 | K16: =F16^2 -> 0 | L16: =G16^2 -> 1 | M16: =$C$38+$C$39*F16+$C$40*G16 -> 0.014279515 | N16: =E16-M16 -> -0.00025426964
A17: =Data!B15 -> 12 | B17: =Data!E15 -> 1 | C17: =Data!D15 -> 5 | D17: =Data!C15 -> 117 | E17: =B17*C17/D17 -> 0.042735043 | F17: =Data!G15 -> 0 | G17: =C17 -> 5 | H17: =F17*E17 -> 0 | I17: =G17*E17 -> 0.21367521 | J17: =F17*G17 -> 0 | K17: =F17^2 -> 0 | L17: =G17^2 -> 25 | M17: =$C$38+$C$39*F17+$C$40*G17 -> 0.042921538 | N17: =E17-M17 -> -0.00018649479
... A21: =Data!B19 -> 16 | B21: =Data!E19 -> 1 | C21: =Data!D19 -> 1 | D21: =Data!C19 -> 41.8 | E21: =B21*C21/D21 -> 0.023923445 | F21: =Data!G19 -> 1 | G21: =C21 -> 1 | H21: =F21*E21 -> 0.023923445 | I21: =G21*E21 -> 0.023923445 | J21: =F21*G21 -> 1 | K21: =F21^2 -> 1 | L21: =G21^2 -> 1 | M21: =$C$38+$C$39*F21+$C$40*G21 -> 0.023276347 | N21: =E21-M21 -> 0.00064709818
A22: Σ | B22: n = | C22: =COUNT(E6:E21) -> 16 | E22: =SUM(E6:E21) -> 0.66223723 | F22: =SUM(F6:F21) -> 12 | G22: =SUM(G6:G21) -> 61.5 | H22: =SUM(H6:H21) -> 0.56721478 | I22: =SUM(I6:I21) -> 5.996716 | J22: =SUM(J6:J21) -> 12 | K22: =SUM(K6:K21) -> 44 | L22: =SUM(L6:L21) -> 761.25
A25: Persamaan normal (Cramer): [A]·[a0; a1; a2] = [b]
B26: Matriks A | F26: Vektor b
B27: =$C$22 -> 16 | C27: =$F$22 -> 12 | D27: =$G$22 -> 61.5 | F27: =$E$22 -> 0.66223723
B28: =$F$22 -> 12 | C28: =$K$22 -> 44 | D28: =$J$22 -> 12 | F28: =$H$22 -> 0.56721478
B29: =$G$22 -> 61.5 | C29: =$J$22 -> 12 | D29: =$L$22 -> 761.25 | F29: =$I$22 -> 5.996716
B31: A0 (kolom 1 diganti b) | F31: A1 (kolom 2 diganti b) | J31: A2 (kolom 3 diganti b)
B32: =$E$22 -> 0.66223723 | C32: =$F$22 -> 12 | D32: =$G$22 -> 61.5 | F32: =$C$22 -> 16 | G32: =$E$22 -> 0.66223723 | H32: =$G$22 -> 61.5 | J32: =$C$22 -> 16 | K32: =$F$22 -> 12 | L32: =$E$22 -> 0.66223723
B33: =$H$22 -> 0.56721478 | C33: =$K$22 -> 44 | D33: =$J$22 -> 12 | F33: =$F$22 -> 12 | G33: =$H$22 -> 0.56721478 | H33: =$J$22 -> 12 | J33: =$F$22 -> 12 | K33: =$K$22 -> 44 | L33: =$H$22 -> 0.56721478
B34: =$I$22 -> 5.996716 | C34: =$J$22 -> 12 | D34: =$L$22 -> 761.25 | F34: =$G$22 -> 61.5 | G34: =$I$22 -> 5.996716 | H34: =$L$22 -> 761.25 | J34: =$G$22 -> 61.5 | K34: =$J$22 -> 12 | L34: =$I$22 -> 5.996716
A36: Hasil
A37: det A | C37: =MDETERM(B27:D29) -> 275289
A38: a0 = 1/k | C38: =MDETERM(B32:D34)/C37 -> 0.0071190095
A39: a1 = KB/k | C39: =MDETERM(F32:H34)/C37 -> 0.0089968317
A40: a2 = KT/k | C40: =MDETERM(J32:L34)/C37 -> 0.0071605056
A41: k (× 10^10) | C41: =1/C38 -> 140.46898
A42: k (g mol/g kat·s·atm²) | C42: =C41*0.0000000001 -> 1.4046898e-08
A43: KB (atm⁻¹) | C43: =C39/C38 -> 1.2637758
A44: KT (atm⁻¹) | C44: =C40/C38 -> 1.0058289
A45: SSE = Σ(y − ŷ)² | C45: =SUMSQ(N6:N21) -> 2.5520371e-06
A46: SST = Σ(y − ȳ)² | C46: =DEVSQ(E6:E21) -> 0.025349795
A47: R² = 1 − SSE/SST | C47: =1-C45/C46 -> 0.99989933
A49: Persamaan hasil regresi: | C49: ="y = "&TEXT($C$38,"0.000000")&" + "&TEXT($C$39,"0.000000")&"·x1 + "&TEXT($C$40,"0.000000")&"·x2" -> y = 0.007119 + 0.008997·x1 + 0.007161·x2
...

Sheet Plot Regresi
A1: Plot Regresi: y = a0 + a1·x1 + a2·x2
A2: ="a0 = "&TEXT(Perhitungan!$C$38,"0.000000")&" a1 = "&TEXT(Perhitungan!$C$39,"0.000000")&" a2 = "&TEXT(Perhitungan!$C$40,"0.000000")&" R² = "&TEXT(Perhitungan!C47,"0.0000") -> a0 = 0.007119 a1 = 0.008997 a2 = 0.007161 R² = 0.9999
A3: Tabel bantu mengambil nilai dari sheet Perhitungan (teks hijau = link antar-sheet).
A5: 1) y data vs ŷ model (semua run)
A6: Run | B6: ŷ model | C6: y data
A7: =Perhitungan!A6 -> 1 | B7: =Perhitungan!M6 -> 0.014279515 | C7: =Perhitungan!E6 -> 0.014084507
A8: =Perhitungan!A7 -> 2 | B8: =Perhitungan!M7 -> 0.014279515 | C8: =Perhitungan!E7 -> 0.014025245
A9: =Perhitungan!A8 -> 3 | B9: =Perhitungan!M8 -> 0.023276347 | C9: =Perhitungan!E8 -> 0.024038462
A10: =Perhitungan!A9 -> 4 | B10: =Perhitungan!M9 -> 0.050266842 | C10: =Perhitungan!E9 -> 0.050761421
A11: =Perhitungan!A10 -> 5 | B11: =Perhitungan!M10 -> 0.023276347 | C11: =Perhitungan!E10 -> 0.023809524
A12: =Perhitungan!A11 -> 6 | B12: =Perhitungan!M11 -> 0.059263674 | C12: =Perhitungan!E11 -> 0.058479532
A13: =Perhitungan!A12 -> 7 | B13: =Perhitungan!M12 -> 0.014279515 | C13: =Perhitungan!E12 -> 0.013927577
A14: =Perhitungan!A13 -> 8 | B14: =Perhitungan!M13 -> 0.014279515 | C14: =Perhitungan!E13 -> 0.014084507
A15: =Perhitungan!A14 -> 9 | B15: =Perhitungan!M14 -> 0.014279515 | C15: =Perhitungan!E14 -> 0.014084507
A16: =Perhitungan!A15 -> 10 | B16: =Perhitungan!M15 -> 0.010699262 | C16: =Perhitungan!E15 -> 0.010638298
A17: =Perhitungan!A16 -> 11 | B17: =Perhitungan!M16 -> 0.014279515 | C17: =Perhitungan!E16 -> 0.014025245
A18: =Perhitungan!A17 -> 12 | B18: =Perhitungan!M17 -> 0.042921538 | C18: =Perhitungan!E17 -> 0.042735043
... A22: =Perhitungan!A21 -> 16 | B22: =Perhitungan!M21 -> 0.023276347 | C22: =Perhitungan!E21 -> 0.023923445
A24: Garis y = ŷ
B25: =0 -> 0 | C25: =0 -> 0
B26: =1.05*MAX(B7:C22) -> 0.15789474 | C26: =B26 -> 0.15789474
A29: 2) y vs x2 = PT (x1 = PB = 0, Set D)
A30: x2 = PT | B30: y data | C30: ŷ model
A31: =Perhitungan!G15 -> 0.5 | B31: =Perhitungan!E15 -> 0.010638298 | C31: =Perhitungan!M15 -> 0.010699262
A32: =Perhitungan!G16 -> 1 | B32: =Perhitungan!E16 -> 0.014025245 | C32: =Perhitungan!M16 -> 0.014279515
A33: =Perhitungan!G17 -> 5 | B33: =Perhitungan!E17 -> 0.042735043 | C33: =Perhitungan!M17 -> 0.042921538
A34: =Perhitungan!G18 -> 10 | B34: =Perhitungan!E18 -> 0.078740157 | C34: =Perhitungan!M18 -> 0.078724066
A35: =Perhitungan!G19 -> 15 | B35: =Perhitungan!E19 -> 0.11450382 | C35: =Perhitungan!M19 -> 0.11452659
A36: =Perhitungan!G20 -> 20 | B36: =Perhitungan!E20 -> 0.15037594 | C36: =Perhitungan!M20 -> 0.15032912
A39: 3) y vs x1 = PB (x2 = PT = 1, PM = 0)
A40: x1 = PB | B40: y data | C40: ŷ model
A41: =Perhitungan!F12 -> 0 | B41: =Perhitungan!E12 -> 0.013927577 | C41: =Perhitungan!M12 -> 0.014279515
A42: =Perhitungan!F8 -> 1 | B42: =Perhitungan!E8 -> 0.024038462 | C42: =Perhitungan!M8 -> 0.023276347
A43: =Perhitungan!F9 -> 4 | B43: =Perhitungan!E9 -> 0.050761421 | C43: =Perhitungan!M9 -> 0.050266842
A44: =Perhitungan!F11 -> 5 | B44: =Perhitungan!E11 -> 0.058479532 | C44: =Perhitungan!M11 -> 0.059263674
